<sdf version='1.9'>
  <model name='rbkairos' canonical_link='summit_xl_base_footprint'>
    <plugin filename="libignition-gazebo-imu-system.so" name="ignition::gazebo::systems::Imu"/>
    <plugin
      filename="libignition-gazebo-sensors-system.so"
      name="ignition::gazebo::systems::Sensors">
      <render_engine>ogre2</render_engine>
    </plugin>

    <self_collide>1</self_collide>

      <frame name="summit_xl_front_laser_link" attached_to='summit_xl_base_footprint'>
        <pose>0.2865 -0.20894 0.3083 3.14159 2.06823e-13 -0.785398</pose>
      </frame>
    <link name='summit_xl_base_footprint'>
      <inertial>
        <pose>0.006538990216393045 -4.829185357226844e-05 0.1433398882740928 0 0 0</pose>
        <mass>131.751</mass>
        <inertia>
          <ixx>2.201281127080626</ixx>
          <ixy>0.1483301209247351</ixy>
          <ixz>-0.302224863433936</ixz>k
          <iyy>7.92557881098813</iyy>
          <iyz>0.001304695710856086</iyz>
          <izz>6.615454002673648</izz>
        </inertia>
      </inertial>
      <collision name='summit_xl_base_footprint_fixed_joint_lump__summit_xl_base_link_collision'>
        <pose>0 0 0.127 0 0 0</pose>
        <geometry>
          <mesh>
            <scale>1 1 1</scale>
            <uri>meshes/summit_xls_chassis.dae</uri>
          </mesh>
        </geometry>
        <surface>
          <contact>
            <ode/>
          </contact>
          <friction>
            <ode/>
          </friction>
        </surface>
      </collision>
      <collision name='summit_xl_base_footprint_fixed_joint_lump__summit_xl_arm_base_link_collision_1'>
        <pose>0.1883 0 0.50912 0 0 2.356194490192345</pose>
        <geometry>
          <mesh>
            <scale>1 1 1</scale>
            <uri>meshes/base.stl</uri>
          </mesh>
        </geometry>
      </collision>
      <collision name='summit_xl_base_footprint_fixed_joint_lump__summit_xl_front_laser_base_link_collision_2'>
        <pose>0.2865 -0.20894 0.4243 3.141592653589793 2.068231071102144e-13 -0.785398163397293</pose>
        <geometry>
          <mesh>
            <scale>1 1 1</scale>
            <uri>meshes/sick_s300.dae</uri>
          </mesh>
        </geometry>
      </collision>
      <collision name='summit_xl_base_footprint_fixed_joint_lump__summit_xl_front_rgbd_camera_link_collision_3'>
        <pose>0.3585 0 0.37762 0 0 0</pose>
        <geometry>
          <mesh>
            <scale>1 1 1</scale>
            <uri>meshes/orbbec_astra.dae</uri>
          </mesh>
        </geometry>
        <surface>
          <contact>
            <ode/>
          </contact>
          <friction>
            <ode/>
          </friction>
        </surface>
      </collision>
      <collision name='summit_xl_base_footprint_fixed_joint_lump__summit_xl_imu_link_collision_4'>
        <pose>0.127 -0.129 0.339 0 0 0</pose>
        <geometry>
          <box>
            <size>0.001 0.001 0.001</size>
          </box>
        </geometry>
      </collision>
      <collision name='summit_xl_base_footprint_fixed_joint_lump__summit_xl_rear_laser_base_link_collision_5'>
        <pose>-0.2865 0.20894 0.4243 3.141592653589793 2.068231071102144e-13 2.356194490192293</pose>
        <geometry>
          <mesh>
            <scale>1 1 1</scale>
            <uri>meshes/sick_s300.dae</uri>
          </mesh>
        </geometry>
      </collision>
      <visual name='summit_xl_base_footprint_visual'>
        <pose>0 0 0 0 0 0</pose>
        <geometry>
          <box>
            <size>0.001 0.001 0.001</size>
          </box>
        </geometry>
      </visual>
      <visual name='summit_xl_base_footprint_fixed_joint_lump__summit_xl_base_link_visual_1'>
        <pose>0 0 0.127 0 0 0</pose>
        <geometry>
          <mesh>
            <scale>1 1 1</scale>
            <uri>meshes/summit_xls_chassis.stl</uri>
          </mesh>
        </geometry>
        <material>
          <specular>0.1 0.1 0.1 1</specular>
          <diffuse>0 0 0 1</diffuse>
          <ambient>0 0 0 1</ambient>
        </material>
      </visual>
      <visual name='summit_xl_base_footprint_fixed_joint_lump__summit_xl_arm_base_link_visual_2'>
        <pose>0.1883 0 0.50912 0 0 2.356194490192345</pose>
        <geometry>
          <mesh>
            <scale>1 1 1</scale>
            <uri>meshes/base.dae</uri>
          </mesh>
        </geometry>
        <!--material>
          <diffuse>0.8749999850988388 0.8749999850988388 0.8749999850988388 1</diffuse>
          <ambient>0.8749999850988388 0.8749999850988388 0.8749999850988388 1</ambient>
        </material -->
      </visual>
      <visual name='summit_xl_base_footprint_fixed_joint_lump__summit_xl_base_logo_front_visual_3'>
        <pose>0.345 0 0.127 0 0 -1.570796326794896</pose>
        <geometry>
          <mesh>
            <scale>1 1 1</scale>
            <uri>meshes/robotnik_logo_chasis.stl</uri>
          </mesh>
        </geometry>
        <material>
          <diffuse>0.625 0.625 0.625 1</diffuse>
          <ambient>0.625 0.625 0.625 1</ambient>
        </material>
      </visual>
      <visual name='summit_xl_base_footprint_fixed_joint_lump__summit_xl_base_logo_left_visual_4'>
        <pose>0 0.28931 0.41762 0 0 0</pose>
        <geometry>
          <mesh>
            <scale>1 1 1</scale>
            <uri>meshes/robotnik_logo_chasis.stl</uri>
          </mesh>
        </geometry>
        <material>
          <diffuse>0.625 0.625 0.625 1</diffuse>
          <ambient>0.625 0.625 0.625 1</ambient>
        </material>
      </visual>
      <visual name='summit_xl_base_footprint_fixed_joint_lump__summit_xl_base_logo_rear_visual_5'>
        <pose>-0.345 0 0.127 0 0 1.570796326794896</pose>
        <geometry>
          <mesh>
            <scale>1 1 1</scale>
            <uri>meshes/robotnik_logo_chasis.stl</uri>
          </mesh>
        </geometry>
        <material>
          <diffuse>0.625 0.625 0.625 1</diffuse>
          <ambient>0.625 0.625 0.625 1</ambient>
        </material>
      </visual>
      <visual name='summit_xl_base_footprint_fixed_joint_lump__summit_xl_base_logo_right_visual_6'>
        <pose>0 -0.28931 0.41762 0 0 3.141592653589793</pose>
        <geometry>
          <mesh>
            <scale>1 1 1</scale>
            <uri>meshes/robotnik_logo_chasis.stl</uri>
          </mesh>
        </geometry>
        <material>
          <diffuse>0.625 0.625 0.625 1</diffuse>
          <ambient>0.625 0.625 0.625 1</ambient>
        </material>
      </visual>
      <visual name='summit_xl_base_footprint_fixed_joint_lump__summit_xl_base_chapa_visual_7'>
        <pose>0 0 0.50762 0 0 0</pose>
        <geometry>
          <mesh>
            <scale>1 1 1</scale>
            <uri>meshes/summit_xls_chapas_inox_tapas.stl</uri>
          </mesh>
        </geometry>
        <material>
          <!--diffuse>0.625 0.625 0.625 1</diffuse>
          <ambient>0.625 0.625 0.625 1</ambient-->
            <diffuse>1.0 1.0 1.0</diffuse>
            <specular>1.0 1.0 1.0</specular>
            <pbr>
                <metal>
                    <albedo_map>materials/textures/TexturesCom_Metal_StainlessClean_512_albedo.png</albedo_map>
                    <normal_map>materials/textures/TexturesCom_Metal_StainlessClean_512_normal.png</normal_map>
                    <metalness_map>materials/textures/TexturesCom_Metal_StainlessClean_512_metallic.png</metalness_map>
                    <roughness_map>materials/textures/TexturesCom_Metal_StainlessClean_512_roughness.png</roughness_map>
                </metal>
            </pbr>
        </material>
      </visual>
      <visual name='summit_xl_base_footprint_fixed_joint_lump__summit_xl_front_laser_base_link_visual_8'>
        <pose>0.2865 -0.20894 0.4243 3.141592653589793 2.068231071102144e-13 -0.785398163397293</pose>
        <geometry>
          <mesh>
            <scale>1 1 1</scale>
            <uri>meshes/sick_s300.dae</uri>
          </mesh>
        </geometry>
        <material>
          <specular>0.1 0.1 0.1 1</specular>
          <diffuse>0 0 0 1</diffuse>
          <ambient>0 0 0 1</ambient>
        </material>
      </visual>
      <visual name='summit_xl_base_footprint_fixed_joint_lump__summit_xl_front_rgbd_camera_link_visual_9'>
        <pose>0.3585 0 0.37762 0 0 0</pose>
        <geometry>
          <mesh>
            <scale>1 1 1</scale>
            <uri>meshes/orbbec_astra.dae</uri>
          </mesh>
        </geometry>
      </visual>
      <visual name='summit_xl_base_footprint_fixed_joint_lump__summit_xl_imu_link_visual_10'>
        <pose>0.127 -0.129 0.339 0 0 0</pose>
        <geometry>
          <box>
            <size>0.001 0.001 0.001</size>
          </box>
        </geometry>
      </visual>
      <visual name='summit_xl_base_footprint_fixed_joint_lump__summit_xl_rear_laser_base_link_visual_11'>
        <pose>-0.2865 0.20894 0.4243 3.141592653589793 2.068231071102144e-13 2.356194490192293</pose>
        <geometry>
          <mesh>
            <scale>1 1 1</scale>
            <uri>meshes/sick_s300.dae</uri>
          </mesh>
        </geometry>
        <material>
          <specular>0.1 0.1 0.1 1</specular>
          <diffuse>0 0 0 1</diffuse>
          <ambient>0 0 0 1</ambient>
        </material>
      </visual>

      <sensor name='summit_xl_front_laser_sensor' type='gpu_lidar'>
        <pose>0.2865 -0.20894 0.3083 3.14159 2.06823e-13 -0.785398</pose>
        <!-- pose relative_to='summit_xl_front_laser_link'>0 0 0 0 0 0</pose -->
        <!--topic>front_laser/scan</topic -->
        <update_rate>12.5</update_rate>
        <lidar>
            <scan>
                <horizontal>
                    <samples>541</samples>
                    <resolution>1</resolution>
                    <min_angle>-2.3562</min_angle>
                    <max_angle>2.3562</max_angle>
                </horizontal>
                <!-- vertical>
                    <samples>1</samples>
                    <resolution>0.03</resolution>
                    <min_angle>0</min_angle>
                    <max_angle>0</max_angle>
                </vertical -->
            </scan>
            <range>
                <min>0.10</min>
                <max>30.0</max>
                <resolution>0.03</resolution>
            </range>
            <noise>
                <type>gaussian</type>
                <mean>0.0</mean>
                <stddev>0.03</stddev>
            </noise>
        </lidar>
        <always_on>1</always_on>
        <visualize>0</visualize>
      </sensor>      
      <!-- sensor name='summit_xl_front_laser_sensor' type='ray'>
        <visualize>false</visualize>
        <update_rate>12.5</update_rate>
        <ray>
          <scan>
            <horizontal>
              <samples>541</samples>
              <resolution>1</resolution>
              <min_angle>-2.3562</min_angle>
              <max_angle>2.3562</max_angle>
            </horizontal>
          </scan>
          <range>
            <min>0.10</min>
            <max>30.0</max>
            <resolution>0.03</resolution>
          </range>
          <noise>
            <type>gaussian</type>
            <mean>0.0</mean>
            <stddev>0.03</stddev>
          </noise>
        </ray>
        <plugin name='summit_xl_front_laser_controller' filename='libgazebo_ros_laser.so'>
          <topicName>front_laser/scan</topicName>
          <frameName>/summit_xl_front_laser_link</frameName>
        </plugin>
        <pose>0.2865 -0.20894 0.3083 3.14159 2.06823e-13 -0.785398</pose>
      </sensor -->
      <sensor name='summit_xl_front_rgbd_camera_depth_sensor' type='rgbd_camera'>
      
    
        <always_on>true</always_on>
        <update_rate>20.0</update_rate>
        <camera>
          <horizontal_fov>1.0471975511965976</horizontal_fov>
          <image>
            <format>R8G8B8</format>
            <width>640</width>
            <height>480</height>
          </image>
          <clip>
            <near>0.05</near>
            <far>100</far>
          </clip>
        </camera>
        <!--plugin name='summit_xl_front_rgbd_camera_controller' filename='libgazebo_ros_openni_kinect.so'>
          <cameraName>front_rgbd_camera</cameraName>
          <alwaysOn>true</alwaysOn>
          <updateRate>10</updateRate>
          <imageTopicName>rgb/image_raw</imageTopicName>
          <depthImageTopicName>depth/image_raw</depthImageTopicName>
          <pointCloudTopicName>depth/points</pointCloudTopicName>
          <cameraInfoTopicName>rgb/camera_info</cameraInfoTopicName>
          <depthImageCameraInfoTopicName>depth/camera_info</depthImageCameraInfoTopicName>
          <frameName>/summit_xl_front_rgbd_camera_depth_optical_frame</frameName>
          <baseline>0.1</baseline>
          <distortion_k1>0.0</distortion_k1>
          <distortion_k2>0.0</distortion_k2>
          <distortion_k3>0.0</distortion_k3>
          <distortion_t1>0.0</distortion_t1>
          <distortion_t2>0.0</distortion_t2>
          <pointCloudCutoff>0.4</pointCloudCutoff>
        </plugin -->
        <pose>0.3585 0 0.37762 0 -0 0</pose>
      </sensor>

      <sensor name='summit_xl_rear_laser_sensor' type='gpu_lidar'>
        <pose>-0.2865 0.20894 0.3083 3.14159 2.06823e-13 2.35619</pose>
        <!-- pose relative_to='summit_xl_rear_laser_link'>0 0 0 0 0 0</pose -->
        <!--topic>rear_laser/scan</topic -->
        <update_rate>12.5</update_rate>
        <lidar>
            <scan>
                <horizontal>
                    <samples>541</samples>
                    <resolution>1</resolution>
                    <min_angle>-2.3562</min_angle>
                    <max_angle>2.3562</max_angle>
                </horizontal>
                <!-- vertical>
                    <samples>1</samples>
                    <resolution>0.03</resolution>
                    <min_angle>0</min_angle>
                    <max_angle>0</max_angle>
                </vertical -->
            </scan>
            <range>
                <min>0.10</min>
                <max>30.0</max>
                <resolution>0.03</resolution>
            </range>
            <noise>
                <type>gaussian</type>
                <mean>0.0</mean>
                <stddev>0.03</stddev>
            </noise>
        </lidar>
        <always_on>1</always_on>
        <visualize>0</visualize>
      </sensor>    
      
        
      <!-- sensor name='summit_xl_rear_laser_sensor' type='ray'>
        <visualize>false</visualize>
        <update_rate>12.5</update_rate>
        <ray>
          <scan>
            <horizontal>
              <samples>541</samples>
              <resolution>1</resolution>
              <min_angle>-2.3562</min_angle>
              <max_angle>2.3562</max_angle>
            </horizontal>
          </scan>
          <range>
            <min>0.10</min>
            <max>30.0</max>
            <resolution>0.03</resolution>
          </range>
          <noise>
            <type>gaussian</type>
            <mean>0.0</mean>
            <stddev>0.03</stddev>
          </noise>
        </ray>
        <plugin name='summit_xl_rear_laser_controller' filename='libgazebo_ros_laser.so'>
          <topicName>rear_laser/scan</topicName>
          <frameName>/summit_xl_rear_laser_link</frameName>
        </plugin>
        <pose>-0.2865 0.20894 0.3083 3.14159 2.06823e-13 2.35619</pose>
      </sensor -->


      <self_collide>true</self_collide>
      <sensor name="imu_sensor" type="imu">
        <alwaysOn>true</alwaysOn>
        <updateRate>50.0</updateRate>
        <pose>0.127 -0.129 0.339 0 -0 0</pose>
        <!--topic>imu</topic-->
      </sensor>
    </link>
    <joint name='summit_xl_arm_shoulder_pan_joint' type='revolute'>
      <pose relative_to='summit_xl_base_footprint'>0.1883 0 0.63642 0 0 2.356194490192345</pose>
      <parent>summit_xl_base_footprint</parent>
      <child>summit_xl_arm_shoulder_link</child>
      <axis>
        <xyz>0 0 1</xyz>
        <limit>
          <!--lower>-3.141592653589793</lower>
          <upper>3.141592653589793</upper -->
            <lower>-6.28319</lower>
            <upper>6.28319</upper>
          <effort>330</effort>
          <velocity>2.16</velocity>
        </limit>
        <dynamics>
          <damping>0</damping>
          <friction>0</friction>
          <spring_reference>0</spring_reference>
          <spring_stiffness>0</spring_stiffness>
        </dynamics>
      </axis>
    </joint>
    <link name='summit_xl_arm_shoulder_link'>
      <pose relative_to='summit_xl_arm_shoulder_pan_joint'>0 0 0 0 0 0</pose>
      <inertial>
        <pose>0 0 0 0 0 0</pose>
        <mass>7.778</mass>
        <inertia>
          <ixx>0.03147431257693659</ixx>
          <ixy>0</ixy>
          <ixz>0</ixz>
          <iyy>0.03147431257693659</iyy>
          <iyz>0</iyz>
          <izz>0.021875625</izz>
        </inertia>
      </inertial>
      <collision name='summit_xl_arm_shoulder_link_collision'>
        <pose>0 0 0 0 0 0</pose>
        <geometry>
          <mesh>
            <scale>1 1 1</scale>
            <uri>meshes/shoulder.stl</uri>
          </mesh>
        </geometry>
        <surface>
          <contact>
            <ode/>
          </contact>
          <friction>
            <ode/>
          </friction>
        </surface>
      </collision>
      <visual name='summit_xl_arm_shoulder_link_visual'>
        <pose>0 0 0 0 0 0</pose>
        <geometry>
          <mesh>
            <scale>1 1 1</scale>
            <uri>meshes/shoulder.dae</uri>
          </mesh>
        </geometry>
        <!--material>
          <diffuse>0.8749999850988388 0.8749999850988388 0.8749999850988388 1</diffuse>
          <ambient>0.8749999850988388 0.8749999850988388 0.8749999850988388 1</ambient>
        </material -->
      </visual>
      <self_collide>1</self_collide>
    </link>
    <joint name='summit_xl_arm_shoulder_lift_joint' type='revolute'>
      <pose relative_to='summit_xl_arm_shoulder_link'>0 0.220941 0 0 1.570796326794897 0</pose>
      <parent>summit_xl_arm_shoulder_link</parent>
      <child>summit_xl_arm_upper_arm_link</child>
      <axis>
        <xyz>0 1 0</xyz>
        <limit>
          <!--lower>-3.141592653589793</lower>
          <upper>3.141592653589793</upper-->
          <lower>-6.28319</lower>
					<upper>6.28319</upper>
          <effort>330</effort>
          <velocity>2.16</velocity>
        </limit>
        <dynamics>
          <damping>0</damping>
          <friction>0</friction>
          <spring_reference>0</spring_reference>
          <spring_stiffness>0</spring_stiffness>
        </dynamics>
      </axis>
    </joint>
    <link name='summit_xl_arm_upper_arm_link'>
      <pose relative_to='summit_xl_arm_shoulder_lift_joint'>0 0 0 0 0 0</pose>
      <inertial>
        <pose>0 -0.045 0.306 0 0 0</pose>
        <mass>12.93</mass>
        <inertia>
          <ixx>0.4217538037984109</ixx>
          <ixy>0</ixy>
          <ixz>0</ixz>
          <iyy>0.4217538037984109</iyy>
          <iyz>0</iyz>
          <izz>0.03636562499999999</izz>
        </inertia>
      </inertial>
      <collision name='summit_xl_arm_upper_arm_link_collision'>
        <pose>0 0 0 0 0 0</pose>
        <geometry>
          <mesh>
            <scale>1 1 1</scale>
            <uri>meshes/upperarm.stl</uri>
          </mesh>
        </geometry>
        <surface>
          <contact>
            <ode/>
          </contact>
          <friction>
            <ode/>
          </friction>
        </surface>
      </collision>
      <visual name='summit_xl_arm_upper_arm_link_visual'>
        <pose>0 0 0 0 0 0</pose>
        <geometry>
          <mesh>
            <scale>1 1 1</scale>
            <uri>meshes/upperarm.dae</uri>
          </mesh>
        </geometry>
        <!--material>
          <diffuse>0.8749999850988388 0.8749999850988388 0.8749999850988388 1</diffuse>
          <ambient>0.8749999850988388 0.8749999850988388 0.8749999850988388 1</ambient>
        </material -->
      </visual>
      <self_collide>1</self_collide>
    </link>
    <joint name='summit_xl_arm_elbow_joint' type='revolute'>
      <pose relative_to='summit_xl_arm_upper_arm_link'>0 -0.1719 0.612 0 0 0</pose>
      <parent>summit_xl_arm_upper_arm_link</parent>
      <child>summit_xl_arm_forearm_link</child>
      <axis>
        <xyz>0 1 0</xyz>
        <limit>
          <lower>-3.141592653589793</lower>
          <upper>3.141592653589793</upper>
          <effort>150</effort>
          <velocity>3.15</velocity>
        </limit>
        <dynamics>
          <damping>0</damping>
          <friction>0</friction>
          <spring_reference>0</spring_reference>
          <spring_stiffness>0</spring_stiffness>
        </dynamics>
      </axis>
    </joint>
    <link name='summit_xl_arm_forearm_link'>
      <pose relative_to='summit_xl_arm_elbow_joint'>0 0 0 0 0 0</pose>
      <inertial>
        <pose>0 0 0.28615 0 0 0</pose>
        <mass>3.87</mass>
        <inertia>
          <ixx>0.1110696940971046</ixx>
          <ixy>0</ixy>
          <ixz>0</ixz>
          <iyy>0.1110696940971046</iyy>
          <iyz>0</iyz>
          <izz>0.010884375</izz>
        </inertia>
      </inertial>
      <collision name='summit_xl_arm_forearm_link_collision'>
        <pose>0 0 0 0 0 0</pose>
        <geometry>
          <mesh>
            <scale>1 1 1</scale>
            <uri>meshes/forearm.stl</uri>
          </mesh>
        </geometry>
        <surface>
          <contact>
            <ode/>
          </contact>
          <friction>
            <ode/>
          </friction>
        </surface>
      </collision>
      <visual name='summit_xl_arm_forearm_link_visual'>
        <pose>0 0 0 0 0 0</pose>
        <geometry>
          <mesh>
            <scale>1 1 1</scale>
            <uri>meshes/forearm.dae</uri>
          </mesh>
        </geometry>
        <!--material>
          <diffuse>0.8749999850988388 0.8749999850988388 0.8749999850988388 1</diffuse>
          <ambient>0.8749999850988388 0.8749999850988388 0.8749999850988388 1</ambient>
        </material-->
      </visual>
      <self_collide>1</self_collide>
    </link>
    <joint name='summit_xl_arm_wrist_1_joint' type='revolute'>
      <pose relative_to='summit_xl_arm_forearm_link'>0 0 0.5723 0 1.570796326794897 0</pose>
      <parent>summit_xl_arm_forearm_link</parent>
      <child>summit_xl_arm_wrist_1_link</child>
      <axis>
        <xyz>0 1 0</xyz>
        <limit>
          <!--lower>-3.141592653589793</lower>
          <upper>3.141592653589793</upper-->
            <lower>-6.28319</lower>
					<upper>6.28319</upper>
          <effort>54</effort>
          <velocity>3.2</velocity>
        </limit>
        <dynamics>
          <damping>0</damping>
          <friction>0</friction>
          <spring_reference>0</spring_reference>
          <spring_stiffness>0</spring_stiffness>
        </dynamics>
      </axis>
    </joint>
    <link name='summit_xl_arm_wrist_1_link'>
      <pose relative_to='summit_xl_arm_wrist_1_joint'>0 0 0 0 0 0</pose>
      <inertial>
        <pose>0 0.1149 0 0 0 0</pose>
        <mass>1.96</mass>
        <inertia>
          <ixx>0.005108247956699999</ixx>
          <ixy>0</ixy>
          <ixz>0</ixz>
          <iyy>0.005108247956699999</iyy>
          <iyz>0</iyz>
          <izz>0.005512499999999999</izz>
        </inertia>
      </inertial>
      <collision name='summit_xl_arm_wrist_1_link_collision'>
        <pose>0 0 0 0 0 0</pose>
        <geometry>
          <mesh>
            <scale>1 1 1</scale>
            <uri>meshes/wrist1.stl</uri>
          </mesh>
        </geometry>
        <surface>
          <contact>
            <ode/>
          </contact>
          <friction>
            <ode/>
          </friction>
        </surface>
      </collision>
      <visual name='summit_xl_arm_wrist_1_link_visual'>
        <pose>0 0 0 0 0 0</pose>
        <geometry>
          <mesh>
            <scale>1 1 1</scale>
            <uri>meshes/wrist1.dae</uri>
          </mesh>
        </geometry>
        <!--material>
          <diffuse>0.8749999850988388 0.8749999850988388 0.8749999850988388 1</diffuse>
          <ambient>0.8749999850988388 0.8749999850988388 0.8749999850988388 1</ambient>
        </material-->
      </visual>
      <self_collide>1</self_collide>
    </link>
    <joint name='summit_xl_arm_wrist_2_joint' type='revolute'>
      <pose relative_to='summit_xl_arm_wrist_1_link'>0 0.1149 0 0 0 0</pose>
      <parent>summit_xl_arm_wrist_1_link</parent>
      <child>summit_xl_arm_wrist_2_link</child>
      <axis>
        <xyz>0 0 1</xyz>
        <limit>
          <!--lower>-3.141592653589793</lower>
          <upper>3.141592653589793</upper -->
          <lower>-6.28319</lower>
					<upper>6.28319</upper>
          <effort>54</effort>
          <velocity>3.2</velocity>
        </limit>
        <dynamics>
          <damping>0</damping>
          <friction>0</friction>
          <spring_reference>0</spring_reference>
          <spring_stiffness>0</spring_stiffness>
        </dynamics>
      </axis>
    </joint>
    <link name='summit_xl_arm_wrist_2_link'>
      <pose relative_to='summit_xl_arm_wrist_2_joint'>0 0 0 0 0 0</pose>
      <inertial>
        <pose>0 0 0.1157 0 0 0</pose>
        <mass>1.96</mass>
        <inertia>
          <ixx>0.005108247956699999</ixx>
          <ixy>0</ixy>
          <ixz>0</ixz>
          <iyy>0.005108247956699999</iyy>
          <iyz>0</iyz>
          <izz>0.005512499999999999</izz>
        </inertia>
      </inertial>
      <collision name='summit_xl_arm_wrist_2_link_collision'>
        <pose>0 0 0 0 0 0</pose>
        <geometry>
          <mesh>
            <scale>1 1 1</scale>
            <uri>meshes/wrist2.stl</uri>
          </mesh>
        </geometry>
        <surface>
          <contact>
            <ode/>
          </contact>
          <friction>
            <ode/>
          </friction>
        </surface>
      </collision>
      <visual name='summit_xl_arm_wrist_2_link_visual'>
        <pose>0 0 0 0 0 0</pose>
        <geometry>
          <mesh>
            <scale>1 1 1</scale>
            <uri>meshes/wrist2.dae</uri>
          </mesh>
        </geometry>
        <!--material>
          <diffuse>0.8749999850988388 0.8749999850988388 0.8749999850988388 1</diffuse>
          <ambient>0.8749999850988388 0.8749999850988388 0.8749999850988388 1</ambient>
        </material -->
      </visual>
      <self_collide>1</self_collide>
    </link>
    <joint name='summit_xl_arm_wrist_3_joint' type='revolute'>
      <pose relative_to='summit_xl_arm_wrist_2_link'>0 0 0.1157 0 0 0</pose>
      <parent>summit_xl_arm_wrist_2_link</parent>
      <child>summit_xl_arm_wrist_3_link</child>
      <axis>
        <xyz>0 1 0</xyz>
        <limit>
          <!--lower>-3.141592653589793</lower>
          <upper>3.141592653589793</upper -->
          <lower>-6.28319</lower>
					<upper>6.28319</upper>
          <effort>54</effort>
          <velocity>3.2</velocity>
        </limit>
        <dynamics>
          <damping>0</damping>
          <friction>0</friction>
          <spring_reference>0</spring_reference>
          <spring_stiffness>0</spring_stiffness>
        </dynamics>
      </axis>
    </joint>
    <link name='summit_xl_arm_wrist_3_link'>
      <pose relative_to='summit_xl_arm_wrist_3_joint'>0 0 0 0 0 0</pose>
      <!--inertial>
        <pose>0.002930066028260615 0.09731706893825473 1.84777312401483e-18 1.570796326794896 0 0</pose>
        <mass>2.697</mass>
        <inertia>
          <ixx>3.003030260147668</ixx>
          <ixy>1.69117416681974e-20</ixy>
          <ixz>-6.200852683164646e-05</ixz>
          <iyy>3.004204135426729</iyy>
          <iyz>1.616858219841087e-18</iyz>
          <izz>3.001422400279062</izz>
        </inertia>
      </inertial-->
      <inertial>
				<pose>0 0.07695 0 1.5708 -0 0</pose>
				<mass>0.202</mass>
				<inertia>
					<ixx>0.000117922</ixx>
					<ixy>0</ixy>
					<ixz>0</ixz>
					<iyy>0.000117922</iyy>
					<iyz>0</iyz>
					<izz>0.000204525</izz>
				</inertia>
			</inertial>
      <collision name='summit_xl_arm_wrist_3_link_collision'>
        <pose>0 0 0 0 0 0</pose>
        <geometry>
          <mesh>
            <scale>1 1 1</scale>
            <uri>meshes/wrist3.stl</uri>
          </mesh>
        </geometry>
        <surface>
          <contact>
            <ode/>
          </contact>
          <friction>
            <ode/>
          </friction>
        </surface>
      </collision>
      <collision name='summit_xl_arm_wrist_3_link_fixed_joint_lump__summit_xl_arm_ee_link_collision_1'>
        <pose>-1.734723475976807e-18 0.08220000000000001 0 0 0 1.570796326794896</pose>
        <geometry>
          <box>
            <size>0.01 0.01 0.01</size>
          </box>
        </geometry>
        <surface>
          <contact>
            <ode/>
          </contact>
          <friction>
            <ode/>
          </friction>
        </surface>
      </collision>
      <collision name='summit_xl_arm_wrist_3_link_fixed_joint_lump__summit_xl_tbp_gripper_base_link_collision_2'>
        <pose>0 0.0922 0 -1.570796326794896 0 0</pose>
        <geometry>
          <mesh>
            <scale>0.001 0.001 0.001</scale>
            <uri>meshes/tbp_tool_holder_collision.stl</uri>
          </mesh>
        </geometry>
        <surface>
          <contact>
            <ode/>
          </contact>
          <friction>
            <ode/>
          </friction>
        </surface>
      </collision>
      <collision name='summit_xl_arm_wrist_3_link_fixed_joint_lump__summit_xl_tbp_gripper_camera_holder_collision_3'>
        <pose>0 0.1052 1.734723475976807e-18 -1.570796326794896 0 0</pose>
        <geometry>
          <mesh>
            <scale>0.001 0.001 0.001</scale>
            <uri>meshes/tbp_cam_holder_collision.stl</uri>
          </mesh>
        </geometry>
      </collision>
      <collision name='summit_xl_arm_wrist_3_link_fixed_joint_lump__summit_xl_wrist_rgbd_link_collision_4'>
        <pose>0.1186737528812423 0.1365722140236686 1.387778780781446e-17 0 -1.570796326794897 5.061454807179586</pose>
        <geometry>
          <cylinder>
            <length>0.026</length>
            <radius>0.0305</radius>
          </cylinder>
        </geometry>
        <surface>
          <contact>
            <ode>
              <kp>10000000000000</kp>
              <kd>1</kd>
            </ode>
          </contact>
          <friction>
            <ode>
              <mu2>1</mu2>
              <fdir1>0 0 0</fdir1>
            </ode>
          </friction>
        </surface>
      </collision>
      <collision name='summit_xl_arm_wrist_3_link_fixed_joint_lump__summit_xl_tbp_gripper_screw_nut_collision_5'>
        <pose>-0.05456575867250597 0.3383594144774671 5.551115123125783e-17 -1.570796326794897 -8.326672684688674e-17 0.522</pose>
        <geometry>
          <cylinder>
            <length>0.035</length>
            <radius>0.015</radius>
          </cylinder>
        </geometry>
      </collision>
      <visual name='summit_xl_arm_wrist_3_link_visual'>
        <pose>0 0 0 0 0 0</pose>
        <geometry>
          <mesh>
            <scale>1 1 1</scale>
            <uri>meshes/wrist3.dae</uri>
          </mesh>
        </geometry>
        <material>
          <diffuse>0.8749999850988388 0.8749999850988388 0.8749999850988388 1</diffuse>
          <ambient>0.8749999850988388 0.8749999850988388 0.8749999850988388 1</ambient>
        </material>
      </visual>
      <visual name='summit_xl_arm_wrist_3_link_fixed_joint_lump__summit_xl_tbp_gripper_base_link_visual_1'>
        <pose>0 0.0922 0 -1.570796326794896 0 0</pose>
        <geometry>
          <mesh>
            <scale>0.001 0.001 0.001</scale>
            <uri>meshes/tbp_tool_holder.stl</uri>
          </mesh>
        </geometry>
        <material>
          <specular>0.1 0.1 0.1 1</specular>
          <diffuse>0 0 0 1</diffuse>
          <ambient>0 0 0 1</ambient>
        </material>
        <!--material>
          <specular>0.01 0.01 0.01 1.000000</specular>
          <diffuse>1 0.625 0.625 1</diffuse>
          <ambient>1 0.625 0.625 1</ambient>
        </material-->
      </visual>
      <visual name='summit_xl_arm_wrist_3_link_fixed_joint_lump__summit_xl_tbp_gripper_camera_holder_visual_2'>
        <pose>0 0.1052 1.734723475976807e-18 -1.570796326794896 0 0</pose>
        <geometry>
          <mesh>
            <scale>0.001 0.001 0.001</scale>
            <uri>meshes/tbp_cam_holder.stl</uri>
          </mesh>
        </geometry>
        <material>
          <diffuse>0.625 0.625 0.625 1</diffuse>
          <ambient>0.625 0.625 0.625 1</ambient>
        </material>
        <!--material>
          <diffuse>1 0.625 0.625 1</diffuse>
          <ambient>1 0.625 0.625 1</ambient>
        </material-->
      </visual>
      <visual name='summit_xl_arm_wrist_3_link_fixed_joint_lump__summit_xl_wrist_rgbd_link_visual_3'>
        <pose>0.1142274913063548 0.1487882181988349 6.938893903907228e-18 0 -1.570796326794897 5.061454807179586</pose>
        <geometry>
          <mesh>
            <scale>1 1 1</scale>
            <uri>meshes/l515.dae</uri>
          </mesh>
        </geometry>
        <material>
          <specular>0.1 0.1 0.1 1</specular>
          <diffuse>0 0 0 1</diffuse>
          <ambient>0 0 0 1</ambient>
        </material>
      </visual>
      <visual name='summit_xl_arm_wrist_3_link_fixed_joint_lump__summit_xl_tbp_gripper_screw_nut_visual_4'>
        <pose>-0.04584 0.32319 5.551115123125783e-17 -1.570796326794897 -8.326672684688674e-17 0.522</pose>
        <geometry>
          <mesh>
            <scale>0.001 0.001 0.001</scale>
            <uri>meshes/tbp_hex_nut_19mm.stl</uri>
          </mesh>
        </geometry>
        <material>
          <specular>0.1 0.1 0.1 1</specular>
          <diffuse>0 0 0 1</diffuse>
          <ambient>0 0 0 1</ambient>
        </material>
      </visual>
      <self_collide>1</self_collide>
      <gravity>true</gravity>
      <!--self_collide>0</self_collide-->
      <enable_wind>0</enable_wind>
      <kinematic>0</kinematic>
      <gravity>1</gravity>
      <!-- sensor name='summit_xl_wrist_rgbdcolor' type='camera'>
        <camera name='summit_xl_wrist_rgbd'>
          <horizontal_fov>1.5707963267948966</horizontal_fov>
          <image>
            <width>1280</width>
            <height>720</height>
            <format>RGB_INT8</format>
          </image>
          <clip>
            <near>0.1</near>
            <far>100</far>
          </clip>
          <noise>
            <type>gaussian</type>
            <mean>0.0</mean>
            <stddev>0.007</stddev>
          </noise>
        </camera>
        <always_on>1</always_on>
        <update_rate>30</update_rate>
        <visualize>1</visualize>
        <pose>0.107309 0.141481 6.93889e-18 1.5708 -0 1.91986</pose>
      </sensor>
      <sensor name='summit_xl_wrist_rgbdired1' type='camera'>
        <camera name='summit_xl_wrist_rgbd'>
          <horizontal_fov>1.5707963267948966</horizontal_fov>
          <image>
            <width>1280</width>
            <height>720</height>
            <format>L_INT8</format>
          </image>
          <clip>
            <near>0.1</near>
            <far>100</far>
          </clip>
          <noise>
            <type>gaussian</type>
            <mean>0.0</mean>
            <stddev>0.05</stddev>
          </noise>
        </camera>
        <always_on>1</always_on>
        <update_rate>90</update_rate>
        <visualize>0</visualize>
        <pose>0.107309 0.141481 6.93889e-18 1.5708 -0 1.91986</pose>
      </sensor>
      <sensor name='summit_xl_wrist_rgbdired2' type='camera'>
        <camera name='summit_xl_wrist_rgbd'>
          <horizontal_fov>1.5707963267948966</horizontal_fov>
          <image>
            <width>1280</width>
            <height>720</height>
            <format>L_INT8</format>
          </image>
          <clip>
            <near>0.1</near>
            <far>100</far>
          </clip>
          <noise>
            <type>gaussian</type>
            <mean>0.0</mean>
            <stddev>0.05</stddev>
          </noise>
        </camera>
        <always_on>1</always_on>
        <update_rate>90</update_rate>
        <visualize>0</visualize>
        <pose>0.107309 0.141481 6.93889e-18 1.5708 -0 1.91986</pose>
      </sensor>
      <sensor name='summit_xl_wrist_rgbddepth' type='depth'>
        <camera name='summit_xl_wrist_rgbd'>
          <horizontal_fov>1.5707963267948966</horizontal_fov>
          <image>
            <width>1280</width>
            <height>720</height>
          </image>
          <clip>
            <near>0.1</near>
            <far>100</far>
          </clip>
          <noise>
            <type>gaussian</type>
            <mean>0.0</mean>
            <stddev>0.100</stddev>
          </noise>
        </camera>
        <always_on>1</always_on>
        <update_rate>90</update_rate>
        <visualize>0</visualize>
        <pose>0.107309 0.141481 6.93889e-18 1.5708 -0 1.91986</pose>
      </sensor -->
    </link>

    <!--plugins for ur-->
		<plugin filename="ignition-gazebo-joint-position-controller-system" name="ignition::gazebo::systems::JointPositionController">
			<joint_name>summit_xl_arm_shoulder_pan_joint</joint_name>
			<p_gain>10000</p_gain>
			<i_gain>100</i_gain>
			<d_gain>500</d_gain>
			<i_max>200.0</i_max>
			<i_min>-200.0</i_min>
		</plugin>
		<plugin filename="ignition-gazebo-joint-position-controller-system" name="ignition::gazebo::systems::JointPositionController">
			<joint_name>summit_xl_arm_shoulder_lift_joint</joint_name>
			<p_gain>50000</p_gain>
			<i_gain>100</i_gain>
			<d_gain>1000</d_gain>
			<i_max>200.0</i_max>
			<i_min>-200.0</i_min>
		</plugin>
		<plugin filename="ignition-gazebo-joint-position-controller-system" name="ignition::gazebo::systems::JointPositionController">
			<joint_name>summit_xl_arm_elbow_joint</joint_name>
			<p_gain>50000.0</p_gain>
			<i_gain>100</i_gain>
			<d_gain>1000</d_gain>
			<i_max>200</i_max>
			<i_min>-200</i_min>
		</plugin>
		<plugin filename="ignition-gazebo-joint-position-controller-system" name="ignition::gazebo::systems::JointPositionController">
			<joint_name>summit_xl_arm_wrist_1_joint</joint_name>
			<p_gain>100.0</p_gain>
			<i_gain>50.0</i_gain>
			<d_gain>10.0</d_gain>
			<i_max>10.0</i_max>
			<i_min>-10.0</i_min>
		</plugin>
		<plugin filename="ignition-gazebo-joint-position-controller-system" name="ignition::gazebo::systems::JointPositionController">
			<joint_name>summit_xl_arm_wrist_2_joint</joint_name>
			<p_gain>75.0</p_gain>
			<i_gain>10</i_gain>
			<d_gain>5</d_gain>
			<i_max>10.0</i_max>
			<i_min>-10.0</i_min>
		</plugin>
		<plugin filename="ignition-gazebo-joint-position-controller-system" name="ignition::gazebo::systems::JointPositionController">
			<joint_name>summit_xl_arm_wrist_3_joint</joint_name>
			<p_gain>25.0</p_gain>
			<i_gain>10</i_gain>
			<d_gain>0.1</d_gain>
			<i_max>10.0</i_max>
			<i_min>-10.0</i_min>
		</plugin>
		<!--joint state publisher-->
		<plugin filename="ignition-gazebo-joint-state-publisher-system" name="ignition::gazebo::systems::JointStatePublisher">
			<joint_name>summit_xl_arm_shoulder_pan_joint</joint_name>
			<joint_name>summit_xl_arm_shoulder_lift_joint</joint_name>
			<joint_name>summit_xl_arm_elbow_joint</joint_name>
			<joint_name>summit_xl_arm_wrist_1_joint</joint_name>
			<joint_name>summit_xl_arm_wrist_2_joint</joint_name>
			<joint_name>summit_xl_arm_wrist_3_joint</joint_name>
		</plugin>







    <joint name='summit_xl_back_left_wheel_joint' type='revolute'>
      <pose relative_to='summit_xl_base_footprint'>-0.2225 0.2045 0.127 0 0 0</pose>
      <parent>summit_xl_base_footprint</parent>
      <child>summit_xl_back_left_wheel_link</child>
      <axis>
        <xyz>0 1 0</xyz>
        <limit>
          <effort>100</effort>
          <velocity>100</velocity>
          <lower>-1e16</lower>
          <upper>1e16</upper>
        </limit>
        <dynamics>
          <spring_reference>0</spring_reference>
          <spring_stiffness>0</spring_stiffness>
        </dynamics>
      </axis>
    </joint>
    <link name='summit_xl_back_left_wheel_link'>
      <pose relative_to='summit_xl_back_left_wheel_joint'>0 0 0 0 0 0</pose>
      <inertial>
        <pose>0 0 0 0 0 0</pose>
        <mass>6.5</mass>
        <inertia>
          <ixx>0.0303095</ixx>
          <ixy>0</ixy>
          <ixz>0</ixz>
          <iyy>0.05241925</iyy>
          <iyz>0</iyz>
          <izz>0.0303095</izz>
        </inertia>
      </inertial>
      <collision name='summit_xl_back_left_wheel_link_collision'>
        <pose>0 0 0 1.570796326795 0 0</pose>
        <geometry>
          <cylinder>
            <length>0.08699999999999999</length>
            <radius>0.127</radius>
          </cylinder>
        </geometry>
        <surface>
          <contact>
            <ode>
              <kp>10000000</kp>
              <kd>1</kd>
            </ode>
          </contact>
          <friction>
            <ode>
              <mu>1</mu>
              <mu2>0</mu2>
              <fdir1 ignition:expressed_in="summit_xl_base_footprint">1 1 0</fdir1>
            </ode>
          </friction>
        </surface>
      </collision>
      <visual name='summit_xl_back_left_wheel_link_visual'>
        <pose>0 0 0 0 0 0</pose>
        <geometry>
          <mesh>
            <scale>1 1 1</scale>
            <uri>meshes/omni_wheel_1.dae</uri>
          </mesh>
        </geometry>
        <!--material>
          <diffuse>0.625 0.625 0.625 1</diffuse>
          <ambient>0.625 0.625 0.625 1</ambient>
        </material-->
      </visual>
      <gravity>true</gravity>
    </link>
    <joint name='summit_xl_back_right_wheel_joint' type='revolute'>
      <pose relative_to='summit_xl_base_footprint'>-0.2225 -0.2045 0.127 0 0 0</pose>
      <parent>summit_xl_base_footprint</parent>
      <child>summit_xl_back_right_wheel_link</child>
      <axis>
        <xyz>0 1 0</xyz>
        <limit>
          <effort>100</effort>
          <velocity>100</velocity>
          <lower>-1e16</lower>
          <upper>1e16</upper>
        </limit>
        <dynamics>
          <spring_reference>0</spring_reference>
          <spring_stiffness>0</spring_stiffness>
        </dynamics>
      </axis>
    </joint>
    <link name='summit_xl_back_right_wheel_link'>
      <pose relative_to='summit_xl_back_right_wheel_joint'>0 0 0 0 0 0</pose>
      <inertial>
        <pose>0 0 0 0 0 0</pose>
        <mass>6.5</mass>
        <inertia>
          <ixx>0.0303095</ixx>
          <ixy>0</ixy>
          <ixz>0</ixz>
          <iyy>0.05241925</iyy>
          <iyz>0</iyz>
          <izz>0.0303095</izz>
        </inertia>
      </inertial>
      <collision name='summit_xl_back_right_wheel_link_collision'>
        <pose>0 0 0 1.570796326795 0 0</pose>
        <geometry>
          <cylinder>
            <length>0.08699999999999999</length>
            <radius>0.127</radius>
          </cylinder>
        </geometry>
        <surface>
          <contact>
            <ode>
              <kp>10000000</kp>
              <kd>1</kd>
            </ode>
          </contact>
          <friction>
            <ode>
              <mu>1</mu>
              <mu2>0</mu2>
              <fdir1 ignition:expressed_in="summit_xl_base_footprint">1 -1 0</fdir1>
            </ode>
          </friction>
        </surface>
      </collision>
      <visual name='summit_xl_back_right_wheel_link_visual'>
        <pose>0 0 0 0 0 0</pose>
        <geometry>
          <mesh>
            <scale>1 1 1</scale>
            <uri>meshes/omni_wheel_2.dae</uri>
          </mesh>
        </geometry>
        <!--material>
          <diffuse>0.625 0.625 0.625 1</diffuse>
          <ambient>0.625 0.625 0.625 1</ambient>
        </material-->
      </visual>
      <gravity>true</gravity>
    </link>
    <joint name='summit_xl_front_left_wheel_joint' type='revolute'>
      <pose relative_to='summit_xl_base_footprint'>0.2225 0.2045 0.127 0 0 0</pose>
      <parent>summit_xl_base_footprint</parent>
      <child>summit_xl_front_left_wheel_link</child>
      <axis>
        <xyz>0 1 0</xyz>
        <limit>
          <effort>100</effort>
          <velocity>100</velocity>
          <lower>-1e16</lower>
          <upper>1e16</upper>
        </limit>
        <dynamics>
          <spring_reference>0</spring_reference>
          <spring_stiffness>0</spring_stiffness>
        </dynamics>
      </axis>
    </joint>
    <link name='summit_xl_front_left_wheel_link'>
      <pose relative_to='summit_xl_front_left_wheel_joint'>0 0 0 0 0 0</pose>
      <inertial>
        <pose>0 0 0 0 0 0</pose>
        <mass>6.5</mass>
        <inertia>
          <ixx>0.0303095</ixx>
          <ixy>0</ixy>
          <ixz>0</ixz>
          <iyy>0.05241925</iyy>
          <iyz>0</iyz>
          <izz>0.0303095</izz>
        </inertia>
      </inertial>
      <collision name='summit_xl_front_left_wheel_link_collision'>
        <pose>0 0 0 1.570796326795 0 0</pose>
        <geometry>
          <cylinder>
            <length>0.08699999999999999</length>
            <radius>0.127</radius>
          </cylinder>
        </geometry>
        <surface>
          <contact>
            <ode>
              <kp>10000000</kp>
              <kd>1</kd>
            </ode>
          </contact>
          <friction>
            <ode>
              <mu>1</mu>
              <mu2>0</mu2>
              <fdir1 ignition:expressed_in="summit_xl_base_footprint">1 -1 0</fdir1>
            </ode>
          </friction>
        </surface>
      </collision>
      <visual name='summit_xl_front_left_wheel_link_visual'>
        <pose>0 0 0 0 0 0</pose>
        <geometry>
          <mesh>
            <scale>1 1 1</scale>
            <uri>meshes/omni_wheel_1.dae</uri>
          </mesh>
        </geometry>
        <!--material>
          <diffuse>0.625 0.625 0.625 1</diffuse>
          <ambient>0.625 0.625 0.625 1</ambient>
        </material-->
      </visual>
      <gravity>true</gravity>
    </link>
    <joint name='summit_xl_front_right_wheel_joint' type='revolute'>
      <pose relative_to='summit_xl_base_footprint'>0.2225 -0.2045 0.127 0 0 0</pose>
      <parent>summit_xl_base_footprint</parent>
      <child>summit_xl_front_right_wheel_link</child>
      <axis>
        <xyz>0 1 0</xyz>
        <limit>
          <effort>100</effort>
          <velocity>100</velocity>
          <lower>-1e16</lower>
          <upper>1e16</upper>
        </limit>
        <dynamics>
          <spring_reference>0</spring_reference>
          <spring_stiffness>0</spring_stiffness>
        </dynamics>
      </axis>
    </joint>
    <link name='summit_xl_front_right_wheel_link'>
      <pose relative_to='summit_xl_front_right_wheel_joint'>0 0 0 0 0 0</pose>
      <inertial>
        <pose>0 0 0 0 0 0</pose>
        <mass>6.5</mass>
        <inertia>
          <ixx>0.0303095</ixx>
          <ixy>0</ixy>
          <ixz>0</ixz>
          <iyy>0.05241925</iyy>
          <iyz>0</iyz>
          <izz>0.0303095</izz>
        </inertia>
      </inertial>
      <collision name='summit_xl_front_right_wheel_link_collision'>
        <pose>0 0 0 1.570796326795 0 0</pose>
        <geometry>
          <cylinder>
            <length>0.08699999999999999</length>
            <radius>0.127</radius>
          </cylinder>
        </geometry>
        <surface>
          <contact>
            <ode>
              <kp>10000000</kp>
              <kd>1</kd>
            </ode>
          </contact>
          <friction>
            <ode>
              <mu>1</mu>
              <mu2>0</mu2>
              <fdir1 ignition:expressed_in="summit_xl_base_footprint">1 1 0</fdir1>
            </ode>
          </friction>
        </surface>
      </collision>
      <visual name='summit_xl_front_right_wheel_link_visual'>
        <pose>0 0 0 0 0 0</pose>
        <geometry>
          <mesh>
            <scale>1 1 1</scale>
            <uri>meshes/omni_wheel_2.dae</uri>
          </mesh>
        </geometry>
        <!--material>
          <diffuse>0.625 0.625 0.625 1</diffuse>
          <ambient>0.625 0.625 0.625 1</ambient>
        </material-->
      </visual>
      <gravity>true</gravity>
    </link>

    <!--plugin name='ros_control' filename='libgazebo_ros_control.so'>
      <robotParam>robot_description</robotParam>
      <controlPeriod>0.001</controlPeriod>
      <robotSimType>gazebo_ros_control/DefaultRobotHWSim</robotSimType>
      <legacyModeNS>true</legacyModeNS>
    </plugin -->



    <!--plugin name='omni_steering' filename='libgazebo_ros_planar_move.so'>
      <commandTopic>robotnik_base_control/cmd_vel</commandTopic>
      <odometryTopic>robotnik_base_control/odom</odometryTopic>
      <odometryFrame>summit_xl_odom</odometryFrame>
      <odometryRate>50.0</odometryRate>
      <robotBaseFrame>summit_xl_base_footprint</robotBaseFrame>
      <publishTF>True</publishTF>
      <enableYAxis>true</enableYAxis>
    </plugin -->

    <plugin filename="libignition-gazebo-mecanum-drive-system.so" name="ignition::gazebo::systems::MecanumDrive">
      <front_left_joint>summit_xl_front_left_wheel_joint</front_left_joint>
      <front_right_joint>summit_xl_front_right_wheel_joint</front_right_joint>
      <back_left_joint>summit_xl_back_left_wheel_joint</back_left_joint>
      <back_right_joint>summit_xl_back_right_wheel_joint</back_right_joint>
      <wheelbase>0.444</wheelbase>
      <wheel_separation>0.409</wheel_separation>
      <wheel_radius>0.127</wheel_radius>
      <odom_publish_frequency>1</odom_publish_frequency>
      <!--topic>cmd_vel</topic>
      <odom_publish_frequency></odom_publish_frequency>
      <topic></topic>
      <odom_topic></odom_topic>
      <tf_topic></tf_topic>
      <frame_id></frame_id>
      <child_frame_id></child_frame_id -->
    </plugin>

    <!--plugin name='summit_xl_imu_controller' filename='libhector_gazebo_ros_imu.so'>
      <alwaysOn>true</alwaysOn>
      <topicName>imu/data</topicName>
      <serviceName>summit_xl_imuimu/service</serviceName>
      <frameId>summit_xl_imu_link</frameId>
      <updateRate>50.0</updateRate>
      <gaussianNoise>0.00</gaussianNoise>
      <yawOffset>0.0</yawOffset>
      <yawDrift>0.0</yawDrift>
      <yawGaussianNoise>0.0</yawGaussianNoise>
      <rateOffset>0.0 0.0 0.0</rateOffset>
      <rateDrift>0.0 0.0 0.0</rateDrift>
      <rateGaussianNoise>0.0 0.0 0.0</rateGaussianNoise>
      <accelOffset>0.0 0.0 0.0</accelOffset>
      <accelDrift>0.0 0.0 0.0</accelDrift>
      <accelGaussianNoise>0.0 0.0 0.0</accelGaussianNoise>
      <bodyName>summit_xl_base_footprint</bodyName>
      <xyzOffset>0.127 -0.129 0.339</xyzOffset>
      <rpyOffset>0 -0 0</rpyOffset>
      <ignition::corrected_offsets>1</ignition::corrected_offsets>
    </plugin-->
    <static>false</static>
    <!--plugin name='summit_xl_wrist_rgbd' filename='librealsense_gazebo_plugin.so'>
      <prefix>summit_xl_wrist_rgbd</prefix>
      <depthUpdateRate>30.0</depthUpdateRate>
      <colorUpdateRate>30.0</colorUpdateRate>
      <infraredUpdateRate>30.0</infraredUpdateRate>
      <depthTopicName>depth/image_raw</depthTopicName>
      <depthCameraInfoTopicName>depth/camera_info</depthCameraInfoTopicName>
      <colorTopicName>color/image_raw</colorTopicName>
      <colorCameraInfoTopicName>color/camera_info</colorCameraInfoTopicName>
      <infrared1TopicName>infra1/image_raw</infrared1TopicName>
      <infrared1CameraInfoTopicName>infra1/camera_info</infrared1CameraInfoTopicName>
      <infrared2TopicName>infra2/image_raw</infrared2TopicName>
      <infrared2CameraInfoTopicName>infra2/camera_info</infrared2CameraInfoTopicName>
      <colorOpticalframeName>summit_xl_wrist_rgbd_depth_optical_frame</colorOpticalframeName>
      <depthOpticalframeName>summit_xl_wrist_rgbd_depth_optical_frame</depthOpticalframeName>
      <infrared1OpticalframeName>summit_xl_wrist_rgbd_left_ir_optical_frame</infrared1OpticalframeName>
      <infrared2OpticalframeName>summit_xl_wrist_rgbd_right_ir_optical_frame</infrared2OpticalframeName>
      <rangeMinDepth>0.2</rangeMinDepth>
      <rangeMaxDepth>10.0</rangeMaxDepth>
      <pointCloud>True</pointCloud>
      <pointCloudTopicName>depth/color/points</pointCloudTopicName>
      <pointCloudCutoff>0.25</pointCloudCutoff>
      <pointCloudCutoffMax>9.0</pointCloudCutoffMax>
    </plugin -->
  </model>
</sdf>
