<?xml version='1.0' encoding='utf-8'?>
<robot name='pioneer3at'>
  <link name='pioneer3at/base_footprint'>
    <inertial>
      <origin xyz='0 0 0.18' rpy='0 -0 0'/>
      <mass value='14'/>
      <inertia ixx='0.147117' ixy='0' ixz='0' iyy='0.334951' iyz='0' izz='0.397834'/>
    </inertial>
    <collision name='collision'>
      <origin xyz='0 0 0.18' rpy='0 -0 0'/>
      <geometry>
        <box size='0.501 0.3 0.19'/>
      </geometry>
    </collision>
    <visual name='visual'>
      <origin xyz='0 0 0.18' rpy='0 -0 0'/>
      <geometry>
        <mesh filename='model://pioneer3at/meshes/chassis.dae' scale='1 1 1'/>
      </geometry>
    </visual>
    <visual name='kinect_visual'>
      <origin xyz='0 0 0.425' rpy='0 -0 0'/>
      <geometry>
        <mesh filename='model://pioneer3at/meshes/kinect.dae' scale='1 1 1'/>
      </geometry>
    </visual>
    <visual name='box_visual'>
      <origin xyz='-0.03 0 0.325' rpy='0 -0 0'/>
      <geometry>
        <box size='0.1 0.1 0.1'/>
      </geometry>
    </visual>
  </link>
  <link name='pioneer3at/right_front_wheel'>
    <inertial>
      <origin xyz='-0.125 0.060019 -0.200994' rpy='-1.5707 0 0'/>
      <mass value='1.5'/>
      <inertia ixx='0.00524062' ixy='0' ixz='0' iyy='0.00524062' iyz='0' izz='0.009075'/>
    </inertial>
    <collision name='collision'>
      <origin xyz='-0.125 0.060019 -0.200994' rpy='-1.5707 0 0'/>
      <geometry>
        <cylinder radius='0.11' length='0.075'/>
      </geometry>
    </collision>
    <visual name='visual'>
      <origin xyz='-0.125 0.060019 -0.200994' rpy='-1.5707 0 0'/>
      <geometry>
        <mesh filename='model://pioneer3at/meshes/wheel.dae' scale='1 1 1'/>
      </geometry>
    </visual>
  </link>
  <link name='pioneer3at/left_front_wheel'>
    <inertial>
      <origin xyz='-0.125 0.059981 0.201006' rpy='-1.5707 0 0'/>
      <mass value='1.5'/>
      <inertia ixx='0.00524062' ixy='0' ixz='0' iyy='0.00524062' iyz='0' izz='0.009075'/>
    </inertial>
    <collision name='collision'>
      <origin xyz='-0.125 0.059981 0.201006' rpy='-1.5707 0 0'/>
      <geometry>
        <cylinder radius='0.11' length='0.075'/>
      </geometry>
    </collision>
    <visual name='visual'>
      <origin xyz='-0.125 0.059981 0.201006' rpy='-1.5707 0 0'/>
      <geometry>
        <mesh filename='model://pioneer3at/meshes/wheel.dae' scale='1 1 1'/>
      </geometry>
    </visual>
  </link>
  <link name='pioneer3at/right_rear_wheel'>
    <inertial>
      <origin xyz='0.125 0.060019 -0.200994' rpy='-1.5707 0 0'/>
      <mass value='1.5'/>
      <inertia ixx='0.00524062' ixy='0' ixz='0' iyy='0.00524062' iyz='0' izz='0.009075'/>
    </inertial>
    <collision name='collision'>
      <origin xyz='0.125 0.060019 -0.200994' rpy='-1.5707 0 0'/>
      <geometry>
        <cylinder radius='0.11' length='0.075'/>
      </geometry>
    </collision>
    <visual name='visual'>
      <origin xyz='0.125 0.060019 -0.200994' rpy='-1.5707 0 0'/>
      <geometry>
        <mesh filename='model://pioneer3at/meshes/wheel.dae' scale='1 1 1'/>
      </geometry>
    </visual>
  </link>
  <link name='pioneer3at/left_rear_wheel'>
    <inertial>
      <origin xyz='0.125 0.059981 0.201006' rpy='-1.5707 0 0'/>
      <mass value='1.5'/>
      <inertia ixx='0.00524062' ixy='0' ixz='0' iyy='0.00524062' iyz='0' izz='0.009075'/>
    </inertial>
    <collision name='collision'>
      <origin xyz='0.125 0.059981 0.201006' rpy='-1.5707 0 0'/>
      <geometry>
        <cylinder radius='0.11' length='0.075'/>
      </geometry>
    </collision>
    <visual name='visual'>
      <origin xyz='0.125 0.059981 0.201006' rpy='-1.5707 0 0'/>
      <geometry>
        <mesh filename='model://pioneer3at/meshes/wheel.dae' scale='1 1 1'/>
      </geometry>
    </visual>
  </link>
  <link name="pioneer3at/front_laser_link"/>
  <joint name="front_laser_joint" type="fixed">
    <origin rpy="0 0 0" xyz="0 0 0.20"/>
    <parent link="pioneer3at/base_footprint"/>
    <child link="pioneer3at/front_laser_link"/>
    <axis xyz="0 0 1"/>
    <limit effort="-1" lower="-1e+16" upper="1e+16" velocity="-1"/>
  </joint>
  <joint name='right_front' type='revolute'>
    <origin xyz='0.125 -0.201 -0.06' rpy='1.5707 -0 0'/>
    <parent link='pioneer3at/base_footprint'/>
    <child link='pioneer3at/right_front_wheel'/>
    <axis xyz='0 9.6e-05 1'/>
    <limit lower='-1e+16' upper='1e+16' effort='-1' velocity='-1'/>
  </joint>
  <joint name='right_rear' type='revolute'>
    <origin xyz='-0.125 -0.201 -0.06' rpy='1.5707 -0 0'/>
    <parent link='pioneer3at/base_footprint'/>
    <child link='pioneer3at/right_rear_wheel'/>
    <axis xyz='0 9.6e-05 1'/>
    <limit lower='-1e+16' upper='1e+16' effort='-1' velocity='-1'/>
  </joint>
  <joint name='left_front' type='revolute'>
    <origin xyz='0.125 0.201 -0.06' rpy='1.5707 -0 0'/>
    <parent link='pioneer3at/base_footprint'/>
    <child link='pioneer3at/left_front_wheel'/>
    <axis xyz='0 9.6e-05 1'/>
    <limit lower='-1e+16' upper='1e+16' effort='-1' velocity='-1'/>
  </joint>
  <joint name='left_rear' type='revolute'>
    <origin xyz='-0.125 0.201 -0.06' rpy='1.5707 -0 0'/>
    <parent link='pioneer3at/base_footprint'/>
    <child link='pioneer3at/left_rear_wheel'/>
    <axis xyz='0 9.6e-05 1'/>
    <limit lower='-1e+16' upper='1e+16' effort='-1' velocity='-1'/>
  </joint>
</robot>

