<sdf version="1.9">
    <model name="Mecanum_lift">
    	<pose>0 0 0 0 0 0</pose>
    	<link name="gt"/>
    	<pose>0 0 0.01 0 0 0</pose>
        <link name="base_footprint">
            <pose relative_to='gt_joint'>0 0 0 0 0 0</pose>
            <inertial>
                <mass>1.14395</mass>
                <inertia>
                    <ixx>0.126164</ixx>
                    <ixy>0</ixy>
                    <ixz>0</ixz>
                    <iyy>0.416519</iyy>
                    <iyz>0</iyz>
                    <izz>0.481014</izz>
                </inertia>
            </inertial>
            <collision name="scissor">
                <pose>-0.03 -0.132 0.708 0 0 0</pose>
                <geometry>
                    <box>
                        <size>2.04 0.936 0.6</size>
                    </box>
                </geometry>
            </collision>
            <collision name="bar_1">
                <pose>-0.042 0.294 1.98 0 1.57 0</pose>
                <geometry>
                    <cylinder>
                        <radius>0.03</radius>
                        <length>1.8</length>
                    </cylinder>
                </geometry>
            </collision>
            <collision name="bar_2">
                <pose>-0.042 0.294 1.578 0 1.57 0</pose>
                <geometry>
                    <cylinder>
                        <radius>0.03</radius>
                        <length>1.8</length>
                    </cylinder>
                </geometry>
            </collision>
            <collision name="bar_3">
                <pose>-0.042 -0.558 1.578 0 1.57 0</pose>
                <geometry>
                    <cylinder>
                        <radius>0.03</radius>
                        <length>1.8</length>
                    </cylinder>
                </geometry>
            </collision>
            <collision name="bar_4">
                <pose>-0.042 -0.558 1.98 0 1.57 0</pose>
                <geometry>
                    <cylinder>
                        <radius>0.03</radius>
                        <length>1.8</length>
                    </cylinder>
                </geometry>
            </collision>
            <visual name="visual">
                <pose>0 0 -0.084 1.57 0 0</pose>
                <geometry>
                    <mesh>
                        <scale>0.6 0.6 0.6</scale>
                        <uri>model://Mecanum_lift/meshes/MecanumLift.dae</uri>
                    </mesh>
                </geometry>
                <material>
                    <diffuse>1.0 1.0 1.0</diffuse>
                    <specular>1.0 1.0 1.0</specular>
                    <pbr>
                        <metal>
                            <albedo_map>model://Mecanum_lift/materials/textures/Forklift_Forklift_BaseColor.png</albedo_map>
                            <normal_map>model://Mecanum_lift/materials/textures/Forklift_Forklift_Normal.png</normal_map>
                            <metalness_map>model://Mecanum_lift/materials/textures/Forklift_Forklift_Metallic.png</metalness_map>
                            <roughness_map>model://Mecanum_lift/materials/textures/Forklift_Forklift_Roughness.png</roughness_map>
                            <environment_map>https://fuel.ignitionrobotics.org/1.0/openrobotics/models/Reflective table/1/files/materials/textures/DepotEnvMap.dds</environment_map>
                        </metal>
                    </pbr>
                    <!-- fallback to script if no PBR support-->
                    <script>
                        <uri>model://Mecanum_lift/materials/scripts/</uri>
                        <uri>model://Mecanum_lift/materials/textures/</uri>
                        <name>UrbanTile/Forklift_Diffuse</name>
                    </script>
                </material>
            </visual>
            <sensor name='mlift_front_laser_sensor' type='gpu_lidar'>
		<pose>0 -0.135 0.20 0 0 0</pose>
		<ignition_frame_id>Mecanum_lift/front_laser_link</ignition_frame_id> 
		<topic>/Mecanum_lift/front_laser</topic>
		<update_rate>10</update_rate>
		<lidar>
		    <scan>
		        <horizontal>
		            <samples>541</samples>
		            <resolution>1</resolution>
		            <min_angle>-3.1415926535897932</min_angle>
		            <max_angle>3.1415926535897932</max_angle>
		        </horizontal>
		    </scan>
		    <range>
		        <min>1.25</min>
		        <max>15.0</max>
		        <resolution>0.03</resolution>
		    </range>
		    <!--noise>
		        <type>gaussian</type>
		        <mean>0.0</mean>
		        <stddev>0.03</stddev>
		    </noise-->
		</lidar>
		<always_on>1</always_on>
		<visualize>1</visualize>
	    </sensor>
        </link>
        <link name="front_right_wheel">
            <pose relative_to='front_right_wheel_joint'>0 0 0 0 0 0</pose>
            <inertial>
                <mass>2</mass>
                <inertia>
                    <ixx>0.145833</ixx>
                    <ixy>0</ixy>
                    <ixz>0</ixz>
                    <iyy>0.145833</iyy>
                    <iyz>0</iyz>
                    <izz>0.125</izz>
                </inertia>
            </inertial>
            <collision name="collision">
                <geometry>
                    <sphere>
                        <radius>0.18</radius>
                    </sphere>
                </geometry>
                <surface>
                    <friction>
                        <ode>
                            <mu>1.0</mu>
                            <mu2>0.0</mu2>
                            <fdir1 ignition:expressed_in="base_footprint">1 1 0</fdir1>
                        </ode>
                    </friction>
                </surface>
            </collision>
            <visual name="visual">
                <geometry>
                    <mesh>
                        <uri>model://Mecanum_lift/meshes/mecanum_wheel_right.STL</uri>
                        <scale>0.0036 0.0036 0.0036</scale>
                    </mesh>
                </geometry>
                <material>
                    <ambient>0 0 0</ambient>
                    <diffuse>0 0 0</diffuse>
                    <specular>1.0 1.0 1.0</specular>
                </material>
            </visual>
        </link>
        <link name="rear_right_wheel">
            <pose relative_to='rear_right_wheel_joint'>0 0 0 0 0 0</pose>
            <inertial>
                <mass>2</mass>
                <inertia>
                    <ixx>0.145833</ixx>
                    <ixy>0</ixy>
                    <ixz>0</ixz>
                    <iyy>0.145833</iyy>
                    <iyz>0</iyz>
                    <izz>0.125</izz>
                </inertia>
            </inertial>
            <collision name="collision">
                <geometry>
                    <sphere>
                        <radius>0.18</radius>
                    </sphere>
                </geometry>
                <surface>
                    <friction>
                        <ode>
                            <mu>1.0</mu>
                            <mu2>0.0</mu2>
                            <fdir1 ignition:expressed_in="base_footprint">1 -1 0</fdir1>
                        </ode>
                    </friction>
                </surface>
            </collision>
            <visual name="visual">
                <geometry>
                    <mesh>
                        <uri>model://Mecanum_lift/meshes/mecanum_wheel_left.STL</uri>
                        <scale>0.0036 0.0036 0.0036</scale>
                    </mesh>
                </geometry>
                <material>
                    <ambient>0 0 0</ambient>
                    <diffuse>0 0 0</diffuse>
                    <specular>1.0 1.0 1.0</specular>
                </material>
            </visual>
        </link>
        <link name="front_left_wheel">
            <pose relative_to='front_left_wheel_joint'>0 0 0 0 0 0</pose>
            <inertial>
                <mass>2</mass>
                <inertia>
                    <ixx>0.145833</ixx>
                    <ixy>0</ixy>
                    <ixz>0</ixz>
                    <iyy>0.145833</iyy>
                    <iyz>0</iyz>
                    <izz>0.125</izz>
                </inertia>
            </inertial>
            <collision name="collision">
                <geometry>
                    <sphere>
                        <radius>0.18</radius>
                    </sphere>
                </geometry>
                <surface>
                    <friction>
                        <ode>
                            <mu>1.0</mu>
                            <mu2>0.0</mu2>
                            <fdir1 ignition:expressed_in="base_footprint">1 -1 0</fdir1>
                        </ode>
                    </friction>
                </surface>
            </collision>
            <visual name="visual">
                <geometry>
                    <mesh>
                        <uri>model://Mecanum_lift/meshes/mecanum_wheel_left.STL</uri>
                        <scale>0.0036 0.0036 0.0036</scale>
                    </mesh>
                </geometry>
                <material>
                    <ambient>0 0 0</ambient>
                    <diffuse>0 0 0</diffuse>
                    <specular>1.0 1.0 1.0</specular>
                </material>
            </visual>
        </link>
        <link name="rear_left_wheel">
            <pose relative_to='rear_left_wheel_joint'>0 0 0 0 0 0</pose>
            <inertial>
                <mass>2</mass>
                <inertia>
                    <ixx>0.145833</ixx>
                    <ixy>0</ixy>
                    <ixz>0</ixz>
                    <iyy>0.145833</iyy>
                    <iyz>0</iyz>
                    <izz>0.125</izz>
                </inertia>
            </inertial>
            <collision name="collision">
                <geometry>
                    <sphere>
                        <radius>0.18</radius>
                    </sphere>
                </geometry>
                <surface>
                    <friction>
                        <ode>
                            <mu>1.0</mu>
                            <mu2>0.0</mu2>
                            <fdir1 ignition:expressed_in="base_footprint">1 1 0</fdir1>
                        </ode>
                    </friction>
                </surface>
            </collision>
            <visual name="visual">
                <geometry>
                    <mesh>
                        <uri>model://Mecanum_lift/meshes/mecanum_wheel_right.STL</uri>
                        <scale>0.0036 0.0036 0.0036</scale>
                    </mesh>
                </geometry>
                <material>
                    <ambient>0 0 0</ambient>
                    <diffuse>0 0 0</diffuse>
                    <specular>1.0 1.0 1.0</specular>
                </material>
            </visual>
        </link>
        <joint name="gt_joint" type="revolute">
            <pose relative_to='gt'>0 0.135 0 0 0 0</pose>
            <parent>gt</parent>
            <child>base_footprint</child>
            <axis>
                <xyz>0 1 0</xyz>
                <limit>
                    <lower>-1.79769e+308</lower>
                    <upper>1.79769e+308</upper>
                </limit>
            </axis>
        </joint>
        <joint name="front_left_wheel_joint" type="revolute">
            <pose relative_to='base_footprint'>0.858 0.282 0.186 0 0 0</pose>
            <parent>base_footprint</parent>
            <child>front_left_wheel</child>
            <axis>
                <xyz>0 1 0</xyz>
                <limit>
                    <lower>-1.79769e+308</lower>
                    <upper>1.79769e+308</upper>
                </limit>
            </axis>
        </joint>
        <joint name="front_right_wheel_joint" type="revolute">
            <pose relative_to='base_footprint'>0.858 -0.552 0.186 0 0 0</pose>
            <parent>base_footprint</parent>
            <child>front_right_wheel</child>
            <axis>
                <xyz>0 1 0</xyz>
                <limit>
                    <lower>-1.79769e+308</lower>
                    <upper>1.79769e+308</upper>
                </limit>
            </axis>
        </joint>
        <joint name="rear_left_wheel_joint" type="revolute">
            <pose relative_to='base_footprint'>-0.93 0.282 0.186 0 0 0</pose>
            <parent>base_footprint</parent>
            <child>rear_left_wheel</child>
            <axis>
                <xyz>0 1 0</xyz>
                <limit>
                    <lower>-1.79769e+308</lower>
                    <upper>1.79769e+308</upper>
                </limit>
            </axis>
        </joint>
        <joint name="rear_right_wheel_joint" type="revolute">
            <pose relative_to='base_footprint'>-0.93 -0.552 0.186 0 0 0</pose>
            <parent>base_footprint</parent>
            <child>rear_right_wheel</child>
            <axis>
                <xyz>0 1 0</xyz>
                <limit>
                    <lower>-1.79769e+308</lower>
                    <upper>1.79769e+308</upper>
                </limit>
            </axis>
        </joint>
        <plugin filename="ignition-gazebo-mecanum-drive-system" name="ignition::gazebo::systems::MecanumDrive">
            <front_left_joint>front_left_wheel_joint</front_left_joint>
            <back_left_joint>rear_left_wheel_joint</back_left_joint>
            <front_right_joint>front_right_wheel_joint</front_right_joint>
            <back_right_joint>rear_right_wheel_joint</back_right_joint>
            <wheel_separation>0.834</wheel_separation>
            <wheelbase>1.788</wheelbase>
            <wheel_radius>0.18</wheel_radius>
            <odom_publish_frequency>10</odom_publish_frequency>
            <topic>Mecanum_lift/cmd_vel</topic>
     	    <odom_topic>Mecanum_lift/odom</odom_topic>
      	    <tf_topic>Mecanum_lift/tf</tf_topic>
      	    <frame_id>Mecanum_lift/odom</frame_id>
            <child_frame_id>Mecanum_lift/base_footprint</child_frame_id>
        </plugin>
    </model>
</sdf>
