

      <model name='human_vehicle'>
      <pose>0 0 0.325 0 0 0</pose>

      <link name='base_footprint'>
        <pose>0 -0 0.1 0 -0 0</pose>
        <inertial>
          <mass>1.14395</mass>
          <inertia>
            <ixx>0.126164</ixx>
            <ixy>0</ixy>
            <ixz>0</ixz>
            <iyy>0.416519</iyy>
            <iyz>0</iyz>
            <izz>0.481014</izz>
          </inertia>
        </inertial>
        <!--visual name='visual'>
          <geometry>
          <cylinder>
          <radius>0.55</radius>
          <length>0.250</length>
          </cylinder>
          </geometry>
          <material>
            <ambient>0.5 0.5 1.0 1</ambient>
            <diffuse>0.5 0.5 1.0 1</diffuse>
            <specular>0.0 0.0 1.0 1</specular>
          </material>
        </visual-->
        <collision name='collision'>
          <geometry>
            <cylinder>
          <radius>0.55</radius>
          <length>0.150</length>
          </cylinder>
          </geometry>
        </collision>
        <sensor name="depth_camera1" type="depth_camera">
        <pose>0 0 4 0 1.570796 0</pose>
          <topic>human_vehicle/depth_camera</topic>
          <camera>
            <horizontal_fov>1.57</horizontal_fov>
            <image>
              <width>800</width>
              <height>600</height>
              <format>R_FLOAT32</format>
            </image>
            <clip>
              <near>0.1</near>
              <far>10.0</far>
            </clip>
            <save enabled="false">
              <path>depth_data</path>
            </save>
          </camera>
          <always_on>1</always_on>
          <update_rate>10</update_rate>
          <visualize>true</visualize>
          </sensor>
          <sensor name="instance_segmentation_camera" type="segmentation">
          <pose>0 0 4 0 1.570796 0</pose>
          <topic>human_vehicle/panoptic</topic>
          <camera>
            <segmentation_type>instance</segmentation_type>
            <horizontal_fov>1.57</horizontal_fov>
            <image>
              <width>800</width>
              <height>600</height>
            </image>
            <clip>
              <near>0.1</near>
              <far>10</far>
            </clip>
            <save enabled="true">
              <path>segmentation_data/instance_camera</path>
            </save>
          </camera>
          <always_on>1</always_on>
          <update_rate>10</update_rate>
          <visualize>true</visualize>
        </sensor>
      </link>

      <link name='left_wheel'>
        <pose>0.0 0.3 -0.075 -1.570707963267948966 0 0</pose>
        <inertial>
          <mass>2</mass>
          <inertia>
            <ixx>0.145833</ixx>
            <ixy>0</ixy>
            <ixz>0</ixz>
            <iyy>0.145833</iyy>
            <iyz>0</iyz>
            <izz>0.125</izz>
          </inertia>
        </inertial>
        <!--visual name='visual'>
          <geometry>
            <sphere>
              <radius>0.15</radius>
            </sphere>
          </geometry>
          <material>
            <ambient>0.5 0.5 1.0 1</ambient>
            <diffuse>0.5 0.5 1.0 1</diffuse>
            <specular>0.0 0.0 1.0 1</specular>
          </material>
        </visual-->
        <collision name='collision'>
          <geometry>
            <sphere>
              <radius>0.15</radius>
            </sphere>
          </geometry>
        </collision>
      </link>

      <link name='right_wheel'>
        <pose>0.0 -0.3 -0.075 -1.570707963267948966 0 0</pose>
        <inertial>
          <mass>2</mass>
          <inertia>
            <ixx>0.145833</ixx>
            <ixy>0</ixy>
            <ixz>0</ixz>
            <iyy>0.145833</iyy>
            <iyz>0</iyz>
            <izz>0.125</izz>
          </inertia>
        </inertial>
        <!--visual name='visual'>
          <geometry>
            <sphere>
              <radius>0.15</radius>
            </sphere>
          </geometry>
          <material>
            <ambient>0.5 0.5 1.0 1</ambient>
            <diffuse>0.5 0.5 1.0 1</diffuse>
            <specular>0.0 0.0 1.0 1</specular>
          </material>
          </visual-->
        <collision name='collision'>
          <geometry>
            <sphere>
              <radius>0.15</radius>
            </sphere>
          </geometry>
        </collision>
      </link>

      <link name='caster'>
        <pose>-0.357138 -0 -0.075 0 -0 0</pose>
        <inertial>
          <mass>1</mass>
          <inertia>
            <ixx>0.1</ixx>
            <ixy>0</ixy>
            <ixz>0</ixz>
            <iyy>0.1</iyy>
            <iyz>0</iyz>
            <izz>0.1</izz>
          </inertia>
        </inertial>
        <!--visual name='visual'>
          <geometry>
            <sphere>
              <radius>0.145</radius>
            </sphere>
          </geometry>
          <material>
            <ambient>0.5 0.5 1.0 1</ambient>
            <diffuse>0.5 0.5 1.0 1</diffuse>
            <specular>0.0 0.0 1.0 1</specular>
          </material>
          </visual-->
        <collision name='collision'>
          <geometry>
            <sphere>
              <radius>0.145</radius>
            </sphere>
          </geometry>
        </collision>
      </link>
      
      <link name='caster_front'>
        <pose>0.357138 -0 -0.075 0 -0 0</pose>
        <inertial>
          <mass>1</mass>
          <inertia>
            <ixx>0.1</ixx>
            <ixy>0</ixy>
            <ixz>0</ixz>
            <iyy>0.1</iyy>
            <iyz>0</iyz>
            <izz>0.1</izz>
          </inertia>
        </inertial>
        <!--visual name='visual'>
          <geometry>
            <sphere>
              <radius>0.145</radius>
            </sphere>
          </geometry>
          <material>
            <ambient>0.5 0.5 1.0 1</ambient>
            <diffuse>0.5 0.5 1.0 1</diffuse>
            <specular>0.0 0.0 1.0 1</specular>
          </material>
          </visual-->
        <collision name='collision'>
          <geometry>
            <sphere>
              <radius>0.145</radius>
            </sphere>
          </geometry>
        </collision>
      </link>
      
      <joint name='front_laser_joint' type='fixed'>
          <!--pose relative_to='base_footprint'>0.000 -0.0 0.25083 3.1415926535897932 0.000 0.000</pose-->
          <pose relative_to='base_footprint'>0.000 -0.0 0.0 3.1415926535897932 0.000 0.000</pose>
      	  <parent>base_footprint</parent>
     	  <child>front_laser_link</child>
      </joint>
    
      <link name="front_laser_link">
      <pose relative_to='front_laser_joint'>0 0 0 0 0 0</pose>
        <sensor name='human_vehicle_front_laser_sensor' type='gpu_lidar'>
        <ignition_frame_id>human_vehicle/front_laser_link</ignition_frame_id> 
        <topic>/human_vehicle/front_laser</topic>
        <update_rate>20</update_rate>
        <lidar>
            <scan>
                <horizontal>
                    <samples>541</samples>
                    <resolution>1</resolution>
                    <min_angle>-3.1415926535897932</min_angle>
                    <max_angle>3.1415926535897932</max_angle>
                </horizontal>
            </scan>
            <range>
                <min>0.56</min>
                <max>15.0</max>
                <resolution>0.03</resolution>
            </range>
            <!--noise>
                <type>gaussian</type>
                <mean>0.0</mean>
                <stddev>0.03</stddev>
            </noise-->
        </lidar>
        <always_on>1</always_on>
        <visualize>0</visualize>
      </sensor>  
      
      <!--visual name='visual'>
          <geometry>
            <sphere>
              <radius>0.05</radius>
            </sphere>
          </geometry>
          <material>
            <ambient>0.5 0.5 1.0 1</ambient>
            <diffuse>0.5 0.5 1.0 1</diffuse>
            <specular>0.0 0.0 1.0 1</specular>
          </material>
          </visual-->
      
      </link>    

      <joint name='left_wheel_joint' type='revolute'>
        <parent>base_footprint</parent>
        <child>left_wheel</child>
        <axis>
          <xyz>0 0 1</xyz>
          <limit>
            <lower>-1.79769e+308</lower>
            <upper>1.79769e+308</upper>
          </limit>
        </axis>
      </joint>

      <joint name='right_wheel_joint' type='revolute'>
        <parent>base_footprint</parent>
        <child>right_wheel</child>
        <axis>
          <xyz>0 0 1</xyz>
          <limit>
            <lower>-1.79769e+308</lower>
            <upper>1.79769e+308</upper>
          </limit>
        </axis>
      </joint>

      <joint name='caster_wheel' type='ball'>
        <parent>base_footprint</parent>
        <child>caster</child>
      </joint>
      
      <joint name='caster_wheel_front' type='ball'>
        <parent>base_footprint</parent>
        <child>caster_front</child>
      </joint>

      <plugin
        filename="ignition-gazebo-diff-drive-system"
        name="ignition::gazebo::systems::DiffDrive">
        <left_joint>left_wheel_joint</left_joint>
        <right_joint>right_wheel_joint</right_joint>
        <wheel_separation>0.6</wheel_separation>
        <wheel_radius>0.15</wheel_radius>
        <odom_publish_frequency>20</odom_publish_frequency>
        <max_linear_acceleration>2.5</max_linear_acceleration>
        <min_linear_acceleration>-2.5</min_linear_acceleration>
        <max_angular_acceleration>3.2</max_angular_acceleration>
        <min_angular_acceleration>-3.2</min_angular_acceleration>
        <max_linear_velocity>0.5</max_linear_velocity>
        <min_linear_velocity>-0.5</min_linear_velocity>
        <max_angular_velocity>1</max_angular_velocity>
        <min_angular_velocity>-1</min_angular_velocity>
        <topic>human_vehicle/cmd_vel</topic>
      	<odom_topic>human_vehicle/odom</odom_topic>
      	<tf_topic>human_vehicle/tf</tf_topic>
      	<frame_id>human_vehicle/odom</frame_id>
        <child_frame_id>human_vehicle/base_footprint</child_frame_id>
      </plugin>
      <plugin
        filename="gz-sim-pose-publisher-system"
        name="gz::sim::systems::PosePublisher">
        <publish_link_pose>false</publish_link_pose>
        <publish_collision_pose>false</publish_collision_pose>
        <publish_visual_pose>false</publish_visual_pose>
        <publish_nested_model_pose>true</publish_nested_model_pose>
        <use_pose_vector_msg>true</use_pose_vector_msg>
        <static_update_frequency>10</static_update_frequency>
      </plugin>
    </model>
    
    

    
    

        <include>
        <name>actor_name</name>
        <pose>0 0 1.0 0 0 0</pose>
        <uri></uri>
    	<plugin filename="ignition-gazebo-follow-actor-system"
              name="ignition::gazebo::systems::FollowActor">
        <target>human_vehicle</target>
        <min_distance>0.01</min_distance>
        <max_distance>15.0</max_distance>
        <velocity>1</velocity>
        <animation_x_vel>1.5</animation_x_vel>
      	</plugin>
        </include>

 
