<sdf version='1.10'>
  <model name='robotino'>
    <link name='base_footprint'>
      <inertial>
        <pose>-0.021000000000000001 0 0.13350000000000001 0 0 0</pose>
        <mass>2.0000000000000002e-05</mass>
        <inertia>
          <ixx>2.000000000245</ixx>
          <ixy>0</ixy>
          <ixz>-2.029999999999999e-09</ixz>
          <iyy>2.0000000170650001</iyy>
          <iyz>0</iyz>
          <izz>2.0000000168200009</izz>
        </inertia>
      </inertial>
      <collision name='base_footprint_collision'>
        <pose>0 0 0.025000000000000001 0 0 0</pose>
        <geometry>
          <cylinder>
            <length>0.050000000000000003</length>
            <radius>0.17999999999999999</radius>
          </cylinder>
        </geometry>
      </collision>
      <collision name='base_footprint_fixed_joint_lump__command_bridge_link_collision_1'>
        <pose>-0.050000000000000003 0 0.13 0 0 1.5707949999999999</pose>
        <geometry>
          <box>
            <size>0.25 0.11 0.16</size>
          </box>
        </geometry>
      </collision>
      <visual name='base_footprint_visual'>
        <pose>0.01 0 0 0 0 1.5707949999999999</pose>
        <geometry>
          <mesh>
            <scale>0.01 0.01 0.01</scale>
            <uri>model://robotino/meshes/parts/robotino_base.dae</uri>
          </mesh>
        </geometry>
      </visual>
      <visual name='base_footprint_fixed_joint_lump__anglebracketusb_link_visual_1'>
        <pose>0.0080000000000000002 0 0.13700000000000001 0 0 1.5707949999999999</pose>
        <geometry>
          <mesh>
            <scale>0.01 0.01 0.01</scale>
            <uri>model://robotino/meshes/parts/angle_bracket_usb_hub.dae</uri>
          </mesh>
        </geometry>
      </visual>
    </link>
    <joint name='wheel0_joint' type='revolute'>
      <pose relative_to='base_footprint'>0.065000000000000002 0.11 0.040000000000000001 0 0 1.0471966666700001</pose>
      <parent>base_footprint</parent>
      <child>wheel0_link</child>
      <axis>
        <xyz>-1 0 0</xyz>
        <limit>
          <lower>-inf</lower>
          <upper>inf</upper>
        </limit>
        <dynamics>
          <spring_reference>0</spring_reference>
          <spring_stiffness>0</spring_stiffness>
        </dynamics>
      </axis>
    </joint>
    <link name='wheel0_link'>
      <pose relative_to='wheel0_joint'>0 0 0 0 0 0</pose>
      <inertial>
        <pose>0 0 0 0 0 0</pose>
        <mass>1.0000000000000001e-05</mass>
        <inertia>
          <ixx>1</ixx>
          <ixy>0</ixy>
          <ixz>0</ixz>
          <iyy>1</iyy>
          <iyz>0</iyz>
          <izz>1</izz>
        </inertia>
      </inertial>
      <visual name='wheel0_link_visual'>
        <pose>0 0 0 0 0 0</pose>
        <geometry>
          <mesh>
            <scale>0.01 0.01 0.01</scale>
            <uri>model://robotino/meshes/parts/robotino_wheel.dae</uri>
          </mesh>
        </geometry>
      </visual>
    </link>
    <joint name='wheel1_joint' type='revolute'>
      <pose relative_to='base_footprint'>-0.13 0 0.040000000000000001 0 0 0</pose>
      <parent>base_footprint</parent>
      <child>wheel1_link</child>
      <axis>
        <xyz>1 0 0</xyz>
        <limit>
          <lower>-inf</lower>
          <upper>inf</upper>
        </limit>
        <dynamics>
          <spring_reference>0</spring_reference>
          <spring_stiffness>0</spring_stiffness>
        </dynamics>
      </axis>
    </joint>
    <link name='wheel1_link'>
      <pose relative_to='wheel1_joint'>0 0 0 0 0 0</pose>
      <inertial>
        <pose>0 0 0 0 0 0</pose>
        <mass>1.0000000000000001e-05</mass>
        <inertia>
          <ixx>1</ixx>
          <ixy>0</ixy>
          <ixz>0</ixz>
          <iyy>1</iyy>
          <iyz>0</iyz>
          <izz>1</izz>
        </inertia>
      </inertial>
      <visual name='wheel1_link_visual'>
        <pose>0 0 0 0 0 0</pose>
        <geometry>
          <mesh>
            <scale>0.01 0.01 0.01</scale>
            <uri>model://robotino/meshes/parts/robotino_wheel.dae</uri>
          </mesh>
        </geometry>
      </visual>
    </link>
    <joint name='wheel2_joint' type='revolute'>
      <pose relative_to='base_footprint'>0.065000000000000002 -0.11 0.040000000000000001 0 0 -1.0471966666700001</pose>
      <parent>base_footprint</parent>
      <child>wheel2_link</child>
      <axis>
        <xyz>-1 0 0</xyz>
        <limit>
          <lower>-inf</lower>
          <upper>inf</upper>
        </limit>
        <dynamics>
          <spring_reference>0</spring_reference>
          <spring_stiffness>0</spring_stiffness>
        </dynamics>
      </axis>
    </joint>
    <link name='wheel2_link'>
      <pose relative_to='wheel2_joint'>0 0 0 0 0 0</pose>
      <inertial>
        <pose>0 0 0 0 0 0</pose>
        <mass>1.0000000000000001e-05</mass>
        <inertia>
          <ixx>1</ixx>
          <ixy>0</ixy>
          <ixz>0</ixz>
          <iyy>1</iyy>
          <iyz>0</iyz>
          <izz>1</izz>
        </inertia>
      </inertial>
      <visual name='wheel2_link_visual'>
        <pose>0 0 0 0 0 0</pose>
        <geometry>
          <mesh>
            <scale>0.01 0.01 0.01</scale>
            <uri>model://robotino/meshes/parts/robotino_wheel.dae</uri>
          </mesh>
        </geometry>
      </visual>
    </link>
  </model>
</sdf>
