<sdf version='1.9'>
  <model name='robotino'>
  
    <pose>0 0 0 0 0 0</pose>
  
    <link name='base_footprint'>
      <inertial>
        <pose>0 0 -0.00013350000000001 0 0 0</pose>
        <mass>20</mass>
        <inertia>
          <ixx>2.000000000245</ixx>
          <ixy>0</ixy>
          <ixz>-2.029999999999999e-09</ixz>
          <iyy>2.0000000170650001</iyy>
          <iyz>0</iyz>
          <izz>2.0000000168200009</izz>
        </inertia>
      </inertial>
      <collision name='base_footprint_collision'>
        <pose>0 0 0.030000000000000001 0 0 0</pose>
        <geometry>
          <cylinder>
            <length>0.050000000000000003</length>
            <radius>0.17999999999999999</radius>
          </cylinder>
        </geometry>
      </collision>

      <collision name='base_footprint_fixed_joint_lump__command_bridge_link_collision_1'>
        <pose>-0.050000000000000003 0 0.13 0 0 1.5707949999999999</pose>
        <geometry>
          <box>
            <size>0.25 0.11 0.16</size>
          </box>
        </geometry>
      </collision>
      <visual name='base_footprint_visual'>
        <pose>0.01 0 0 0 0 1.5707949999999999</pose>
        <geometry>
          <mesh>
            <scale>0.01 0.01 0.01</scale>
            <uri>model://robotino/meshes/parts/base.dae</uri>
          </mesh>
        </geometry>
      </visual>
      <visual name='base_footprint_fixed_joint_lump__anglebracketusb_link_visual_1'>
        <pose>0.0080000000000000002 0 0.13700000000000001 0 0 1.5707949999999999</pose>
        <geometry>
          <mesh>
            <scale>0.01 0.01 0.01</scale>
            <uri>model://robotino/meshes/parts/angle_bracket_usb_hub.dae</uri>
          </mesh>
        </geometry>
      </visual>
      <visual name='wheel0_link_visual'>
        <pose>0.065000000000000002 0.11 0.040000000000000001 0 0 1.0471966666700001</pose>
        <geometry>
          <mesh>
            <scale>0.01 0.01 0.01</scale>
            <uri>model://robotino/meshes/parts/wheel.dae</uri>
          </mesh>
        </geometry>
      </visual>
      <visual name='wheel2_link_visual'>
        <pose>0.065000000000000002 -0.11 0.040000000000000001 0 0 -1.0471966666700001</pose>
        <geometry>
          <mesh>
            <scale>0.01 0.01 0.01</scale>
            <uri>model://robotino/meshes/parts/wheel.dae</uri>
          </mesh>
        </geometry>
      </visual>
      <sensor name='robotino_front_laser_sensor' type='gpu_lidar'>
        <pose>0 0 0.20 0 0 0</pose>
        <ignition_frame_id>robotino/front_laser_link</ignition_frame_id> 
        <topic>/robotino/front_laser</topic>
        <update_rate>10</update_rate>
        <lidar>
            <scan>
                <horizontal>
                    <samples>541</samples>
                    <resolution>1</resolution>
                    <min_angle>-3.1415926535897932</min_angle>
                    <max_angle>3.1415926535897932</max_angle>
                </horizontal>
            </scan>
            <range>
                <min>0.2</min>
                <max>15.0</max>
                <resolution>0.03</resolution>
            </range>
            <!--noise>
                <type>gaussian</type>
                <mean>0.0</mean>
                <stddev>0.03</stddev>
            </noise-->
        </lidar>
        <always_on>1</always_on>
        <visualize>1</visualize>
      </sensor>
      
    </link>
    <joint name='wheel0_joint' type='revolute'>
      <pose relative_to='base_footprint'>0.065000000000000002 0.11 0.040000000000000001 0 0 0</pose>
      <parent>base_footprint</parent>
      <child>wheel0_link</child>
      <axis>
        <xyz>0 1 0</xyz>
        <limit>
          <lower>-inf</lower>
          <upper>inf</upper>
        </limit>
        <dynamics>
          <spring_reference>0</spring_reference>
          <spring_stiffness>0</spring_stiffness>
        </dynamics>
      </axis>
    </joint>
    <link name='wheel0_link'>
      <pose relative_to='wheel0_joint'>0 0 0 0 0 0</pose>
      <inertial>
        <pose>0 0 0 0 0 1.0471966666700001</pose>
        <mass>1.0000000000000001e-05</mass>
        <inertia>
          <ixx>1</ixx>
          <ixy>0</ixy>
          <ixz>0</ixz>
          <iyy>1</iyy>
          <iyz>0</iyz>
          <izz>1</izz>
        </inertia>
      </inertial>
      
      <collision name="wheel0_col">
       <pose>0 0 0 -1.570796326794896 0 0</pose>
        <geometry>
          <cylinder>
            <length>0.02</length>
            <radius>0.04</radius>
          </cylinder>
        </geometry>
      </collision>
    </link>
    <joint name='wheel1_joint' type='revolute'>
      <pose relative_to='base_footprint'>-0.13 0 0.040000000000000001 0 0 0</pose>
      <parent>base_footprint</parent>
      <child>wheel1_link</child>
      <axis>
        <xyz>1 0 0</xyz>
        <limit>
          <lower>-inf</lower>
          <upper>inf</upper>
        </limit>
        <dynamics>
          <spring_reference>0</spring_reference>
          <spring_stiffness>0</spring_stiffness>
        </dynamics>
      </axis>
    </joint>
    <link name='wheel1_link'>
      <pose relative_to='wheel1_joint'>0 0 0 0 0 0</pose>
      <inertial>
        <mass>1.0000000000000001e-05</mass>
        <inertia>
          <ixx>1</ixx>
          <ixy>0</ixy>
          <ixz>0</ixz>
          <iyy>1</iyy>
          <iyz>0</iyz>
          <izz>1</izz>
        </inertia>
      </inertial>
      <visual name='wheel1_link_visual'>
        <geometry>
          <mesh>
            <scale>0.01 0.01 0.01</scale>
            <uri>model://robotino/meshes/parts/wheel.dae</uri>
          </mesh>
        </geometry>
      </visual>
    </link>
    <joint name='wheel2_joint' type='revolute'>
      <pose relative_to='base_footprint'>0.065000000000000002 -0.11 0.040000000000000001 0 0 0</pose>
      <parent>base_footprint</parent>
      <child>wheel2_link</child>
      <axis>
        <xyz>0 1 0</xyz>
        <limit>
          <lower>-inf</lower>
          <upper>inf</upper>
        </limit>
        <dynamics>
          <spring_reference>0</spring_reference>
          <spring_stiffness>0</spring_stiffness>
        </dynamics>
      </axis>
    </joint>
    <link name='wheel2_link'>
      <pose relative_to='wheel2_joint'>0 0 0 0 0 0</pose>
      <inertial>
        <pose>0 0 0 0 0 -1.0471966666700001</pose>
        <mass>1.0000000000000001e-05</mass>
        <inertia>
          <ixx>1</ixx>
          <ixy>0</ixy>
          <ixz>0</ixz>
          <iyy>1</iyy>
          <iyz>0</iyz>
          <izz>1</izz>
        </inertia>
      </inertial>
      
      <collision name="wheel0_col">
       <pose>0 0 0 -1.570796326794896 0 0</pose>
        <geometry>
          <cylinder>
            <length>0.02</length>
            <radius>0.04</radius>
          </cylinder>
        </geometry>
      </collision>
    </link>
    <plugin
        filename="ignition-gazebo-diff-drive-system"
        name="ignition::gazebo::systems::DiffDrive">
        <left_joint>wheel0_joint</left_joint>
        <right_joint>wheel2_joint</right_joint>
        <wheel_separation>0.22</wheel_separation>
        <wheel_radius>0.04</wheel_radius>
        <odom_publish_frequency>10</odom_publish_frequency>
        <max_linear_acceleration>0.5</max_linear_acceleration>
        <min_linear_acceleration>-0.5</min_linear_acceleration>
        <max_angular_acceleration>1.5</max_angular_acceleration>
        <min_angular_acceleration>-1.5</min_angular_acceleration>
        <max_linear_velocity>0.1</max_linear_velocity>
        <min_linear_velocity>-0.1</min_linear_velocity>
        <max_angular_velocity>0.5</max_angular_velocity>
        <min_angular_velocity>-0.5</min_angular_velocity>
        <topic>robotino/cmd_vel</topic>
      	<odom_topic>robotino/odom</odom_topic>
      	<tf_topic>robotino/tf</tf_topic>
      	<frame_id>robotino/odom</frame_id>
        <child_frame_id>robotino/base_footprint</child_frame_id>
      </plugin>
    
  </model>
</sdf>
