<?xml version='1.0' encoding='utf-8'?>
<robot name='pioneer3dx_migration_sensor_config_1'>
  <link name='pioneer3dx_migration_sensor_config_1/base_footprint'>
    <inertial>
      <origin xyz='-0.049981 0 0.000673' rpy='0 -0 0'/>
      <mass value='3.51011'/>
      <inertia ixx='3.00055' ixy='0' ixz='-1.52923e-05' iyy='3.00055' iyz='0' izz='3'/>
    </inertial>
    <collision name='base_footprint_collision'>
      <origin xyz='-0.045 0 0.145' rpy='0 -0 0'/>
      <geometry>
        <box size='0.35 0.25 0.14'/>
      </geometry>
    </collision>
    <collision name='base_footprint_fixed_joint_lump__front_sonar_collision_1'>
      <origin xyz='0.109 0 0.209' rpy='0 -0 0'/>
      <geometry>
        <box size='0.01 0.01 0.01'/>
      </geometry>
    </collision>
    <collision name='base_footprint_fixed_joint_lump__top_plate_collision_2'>
      <origin xyz='-0.045 0 0.234' rpy='0 -0 0'/>
      <geometry>
        <box size='0.45 0.38 0.01'/>
      </geometry>
    </collision>
    <collision name='base_footprint_fixed_joint_lump__lms100_collision_3'>
      <origin xyz='0.16 0 0.15' rpy='0 -0 0'/>
      <geometry>
        <box size='0.1 0.1 0.1'/>
      </geometry>
    </collision>
    <visual name='kinect_visual'>
      <origin xyz='0 0 0.385' rpy='0 -0 0'/>
      <geometry>
        <mesh filename='model://pioneer3dx_migration_sensor_config_1/meshes/kinect.dae' scale='1 1 1'/>
      </geometry>
    </visual>
    <visual name='box_visual'>
      <origin xyz='-0.03 0 0.285' rpy='0 -0 0'/>
      <geometry>
        <box size='0.1 0.1 0.1'/>
      </geometry>
    </visual>
    <visual name='base_footprint_fixed_joint_lump__base_visual_visual'>
      <origin xyz='-0.045 0 0.148' rpy='0 -0 0'/>
      <geometry>
        <mesh filename='model://pioneer3dx_migration_sensor_config_1/meshes/chassis.stl' scale='1 1 1'/>
      </geometry>
    </visual>
    <visual name='base_footprint_fixed_joint_lump__front_sonar_vis_visual_1'>
      <origin xyz='0.109 0 0.209' rpy='0 -0 0'/>
      <geometry>
        <mesh filename='model://pioneer3dx_migration_sensor_config_1/meshes/front_sonar.stl' scale='1 1 1'/>
      </geometry>
    </visual>
    <visual name='base_footprint_fixed_joint_lump__base_visual_visual_2'>
      <origin xyz='-0.045 0 0.234' rpy='0 -0 0'/>
      <geometry>
        <mesh filename='model://pioneer3dx_migration_sensor_config_1/meshes/top.stl' scale='1 1 1'/>
      </geometry>
    </visual>
    <visual name='base_footprint_fixed_joint_lump__lms100_visual_3'>
      <origin xyz='0.16 0 0.15' rpy='0 -0 0'/>
      <geometry>
        <mesh filename='model://pioneer3dx_migration_sensor_config_1/meshes/lms100.dae' scale='1 1 1'/>
      </geometry>
    </visual>
  </link>
  <sensor name='pioneer3dx_front_laser_sensor' update_rate='20'>
    <parent link='pioneer3dx_migration_sensor_config_1/base_footprint'/>
    <origin xyz='-0.045 0 0.305' rpy='0 -0 0'/>
  </sensor>
  <link name='pioneer3dx_migration_sensor_config_1/p3dx_left_wheel'>
    <inertial>
      <origin xyz='0 -0.158 -0.091' rpy='0 -0 0'/>
      <mass value='0.51'/>
      <inertia ixx='0.0248235' ixy='0' ixz='0' iyy='0.0304363' iyz='0' izz='0.023528'/>
    </inertial>
    <collision name='p3dx_left_wheel_collision'>
      <origin xyz='0 -0.158 -0.091' rpy='-1.5708 0 0'/>
      <geometry>
        <cylinder radius='0.09' length='0.01'/>
      </geometry>
    </collision>
    <collision name='p3dx_left_wheel_fixed_joint_lump__p3dx_left_hubcap_collision_1'>
      <origin xyz='0 -0.158 -0.091' rpy='0 -0 0'/>
      <geometry>
        <box size='0.01 0.01 0.01'/>
      </geometry>
    </collision>
    <visual name='p3dx_left_wheel_fixed_joint_lump__base_visual_visual'>
      <origin xyz='0 -0.158 -0.091' rpy='0 -0 0'/>
      <geometry>
        <mesh filename='model://pioneer3dx_migration_sensor_config_1/meshes/left_wheel.stl' scale='1 1 1'/>
      </geometry>
    </visual>
    <visual name='p3dx_left_wheel_fixed_joint_lump__base_visual_visual_1'>
      <origin xyz='0 -0.158 -0.091' rpy='0 -0 0'/>
      <geometry>
        <mesh filename='model://pioneer3dx_migration_sensor_config_1/meshes/left_hubcap.stl' scale='1 1 1'/>
      </geometry>
    </visual>
  </link>
  <link name='pioneer3dx_migration_sensor_config_1/p3dx_right_wheel'>
    <inertial>
      <origin xyz='0 0.158 -0.091' rpy='0 -0 0'/>
      <mass value='0.51'/>
      <inertia ixx='0.0248235' ixy='0' ixz='0' iyy='0.0304363' iyz='0' izz='0.023528'/>
    </inertial>
    <collision name='p3dx_right_wheel_collision'>
      <origin xyz='0 0.158 -0.091' rpy='-1.5708 0 0'/>
      <geometry>
        <cylinder radius='0.09' length='0.01'/>
      </geometry>
    </collision>
    <collision name='p3dx_right_wheel_fixed_joint_lump__p3dx_right_hubcap_collision_1'>
      <origin xyz='0 0.158 -0.091' rpy='0 -0 0'/>
      <geometry>
        <box size='0.01 0.01 0.01'/>
      </geometry>
    </collision>
    <visual name='p3dx_right_wheel_fixed_joint_lump__base_visual_visual'>
      <origin xyz='0 0.158 -0.091' rpy='0 -0 0'/>
      <geometry>
        <mesh filename='model://pioneer3dx_migration_sensor_config_1/meshes/right_wheel.stl' scale='1 1 1'/>
      </geometry>
    </visual>
    <visual name='p3dx_right_wheel_fixed_joint_lump__base_visual_visual_1'>
      <origin xyz='0 0.158 -0.091' rpy='0 -0 0'/>
      <geometry>
        <mesh filename='model://pioneer3dx_migration_sensor_config_1/meshes/right_hubcap.stl' scale='1 1 1'/>
      </geometry>
    </visual>
  </link>
  <link name='pioneer3dx_migration_sensor_config_1/swivel'>
    <inertial>
      <origin xyz='0.185 0 -0.055' rpy='0 -0 0'/>
      <mass value='0.1'/>
      <inertia ixx='0.01' ixy='0' ixz='0' iyy='0.01' iyz='0' izz='0.01'/>
    </inertial>
    <collision name='swivel_collision'>
      <origin xyz='0.185 0 -0.055' rpy='0 -0 0'/>
      <geometry>
        <box size='0.01 0.01 0.01'/>
      </geometry>
    </collision>
    <visual name='swivel_fixed_joint_lump__base_visual_visual'>
      <origin xyz='0.185 0 -0.055' rpy='0 -0 0'/>
      <geometry>
        <mesh filename='model://pioneer3dx_migration_sensor_config_1/meshes/swivel.stl' scale='1 1 1'/>
      </geometry>
    </visual>
  </link>
  <link name='pioneer3dx_migration_sensor_config_1/center_wheel'>
    <inertial>
      <origin xyz='0.025682 0 0.015909' rpy='0 -0 0'/>
      <mass value='0.11'/>
      <inertia ixx='0.0248235' ixy='-0.00142347' ixz='0.00100543' iyy='0.0304364' iyz='-8.54693e-06' izz='0.0235281'/>
    </inertial>
    <collision name='center_wheel_collision'>
      <origin xyz='0.026 0 0.016' rpy='-1.5708 0 0'/>
      <geometry>
        <cylinder radius='0.0375' length='0.01'/>
      </geometry>
    </collision>
    <collision name='center_wheel_fixed_joint_lump__center_hubcap_collision_1'>
      <origin xyz='0.0225 0 0.015' rpy='0 -0 0'/>
      <geometry>
        <box size='0.01 0.01 0.01'/>
      </geometry>
    </collision>
    <visual name='center_wheel_fixed_joint_lump__base_visual_visual'>
      <origin xyz='0.026 0 0.016' rpy='0 -0 0'/>
      <geometry>
        <mesh filename='model://pioneer3dx_migration_sensor_config_1/meshes/center_wheel.stl' scale='1 1 1'/>
      </geometry>
    </visual>
    <visual name='center_wheel_fixed_joint_lump__base_visual_visual_1'>
      <origin xyz='0.0225 0 0.015' rpy='0 -0 0'/>
      <geometry>
        <mesh filename='model://pioneer3dx_migration_sensor_config_1/meshes/center_hubcap.stl' scale='1 1 1'/>
      </geometry>
    </visual>
  </link>
  <link name="pioneer3dx_migration_sensor_config_1/front_laser_link"/>
  <joint name="front_laser_joint" type="fixed">
    <origin rpy="0 0 0" xyz="-0.045 0 0.305"/>
    <parent link="pioneer3dx_migration_sensor_config_1/base_footprint"/>
    <child link="pioneer3dx_migration_sensor_config_1/front_laser_link"/>
    <axis xyz="0 0 1"/>
    <limit effort="-1" lower="-1e+16" upper="1e+16" velocity="-1"/>
  </joint>
  <joint name='base_left_wheel_joint' type='revolute'>
    <origin xyz='0 0.158 0.091' rpy='0 -0 0'/>
    <parent link='pioneer3dx_migration_sensor_config_1/base_footprint'/>
    <child link='pioneer3dx_migration_sensor_config_1/p3dx_left_wheel'/>
    <dynamics damping='0' friction='0' />
    <axis xyz='0 1 0'/>
    <limit lower='-1e+16' upper='1e+16' effort='100' velocity='100'/>
  </joint>
  <joint name='base_right_wheel_joint' type='revolute'>
    <origin xyz='0 -0.158 0.091' rpy='0 -0 0'/>
    <parent link='pioneer3dx_migration_sensor_config_1/base_footprint'/>
    <child link='pioneer3dx_migration_sensor_config_1/p3dx_right_wheel'/>
    <dynamics damping='0' friction='0' />
    <axis xyz='0 1 0'/>
    <limit lower='-1e+16' upper='1e+16' effort='100' velocity='100'/>
  </joint>
  <joint name='base_swivel_joint' type='revolute'>
    <origin xyz='-0.185 0 0.055' rpy='0 -0 0'/>
    <parent link='pioneer3dx_migration_sensor_config_1/base_footprint'/>
    <child link='pioneer3dx_migration_sensor_config_1/swivel'/>
    <dynamics damping='0' friction='0' />
    <axis xyz='0 0 1'/>
    <limit lower='-1e+16' upper='1e+16' effort='100' velocity='100'/>
  </joint>
  <joint name='swivel_hubcap_joint' type='revolute'>
    <origin xyz='-0.026 0 -0.016' rpy='0 -0 0'/>
    <parent link='pioneer3dx_migration_sensor_config_1/swivel'/>
    <child link='pioneer3dx_migration_sensor_config_1/center_wheel'/>
    <dynamics damping='0' friction='0' />
    <axis xyz='0 1 0'/>
    <limit lower='-1e+16' upper='1e+16' effort='100' velocity='100'/>
  </joint>
</robot>

